Workbook
Name Pay: #REF!
Name Payments: #REF!
Name pick: #REF!
Name Status: #REF!
Name Type: #REF!
Name Pay: #REF!
Name Payments: #REF!
Name pick: #REF!
Name Status: #REF!
Name Type: #REF!
Name 切片器_月份: #N/A
Name may: #REF!
Name 结果: #REF!
Name 每日: #REF!
Name 我: #REF!
Name Pay: #REF!
Name Payments: #REF!
Name pick: #REF!
Name Status: #REF!
Name Type: #REF!
Name may: #REF!
Name 结果: #REF!
Name 每日: #REF!
Name 我: #REF!

Sheet Summary
B1: FY2026年6月度Payroll薪酬表
B2: HRO｜开弈集团 | P2: 15000 | Q2: 元/年
B3: 账期：202606 | D3: h=d+c+b+e+f1 | F3: d | G3: c | H3: b | I3: e | N3: f1 | P3: 1250 | Q3: 元/月
H4: 每月固定部分 | I4: 每月固定部分 | N4: 每月固定部分 | O4: 福利费
C6: 成本中心(BU) | D6: 企业人力成本总计 | F6: 实收工资 | G6: 个人所得税 | H6: 法定社会保险 （公司成本） | I6: 法定社会保险 （代扣个人） | K6: 绩效&佣金合计&津贴 | L6: 已包含 考勤调整 | N6: 商业保险（公司成本） | O6: 预提福利费
B7: 集团IIT | C7: G-集团管理层 | D7: 106908.76 | E7: 2 | F7: 94463.13 | G7: 2036.87 | H7: 6540 | I7: 3500 | K7: 0 | N7: 368.76 | O7: 1250
C8: G-Jenny-家庭 | D8: 16328.25 | E8: 2 | F8: 15295.46 | G8: 704.54 | H8: 0 | I8: 0 | K8: 0 | L8: 0 | N8: 328.25 | O8: 2500
C9: G-香港办 | D9: 64050 | E9: 3 | F9: 57950 | H9: 3050 | I9: 3050 | K9: 0 | L9: 0
C10: G-管培生 | D10: 36928.73 | E10: 5 | F10: 36774.62 | G10: 154.11 | H10: 0 | K10: 0 | L10: 4928.73 | O10: 5000
C11: G-时代人才 | D11: 35605.69 | E11: 2 | F11: 30348.71 | G11: 1728.66 | H11: 2253.22 | I11: 1119.3 | K11: 0 | L11: 0 | N11: 155.8 | O11: 1250
C12: F-大财务部 | D12: 98963.6 | E12: 5 | F12: 64661.44 | G12: 4791.96 | H12: 18175.44 | I12: 10119.6 | K12: 9403 | L12: 0 | N12: 1215.16 | O12: 6250
C13: F-账务部 | D13: 70615.57 | E13: 4 | F13: 44945.59 | G13: 1600.59 | H13: 15412.49 | I13: 7922.1 | K13: -1231.72 | L13: 0 | N13: 734.8 | O13: 5000
C14: 公司费用-待结算&法人&智名 | D14: 15890.32 | E14: 12 | F14: 11560 | G14: 440 | H14: 2434.22 | I14: 1300.3 | K14: 0 | N14: 155.8
B15: 靠普 | C15: Shaun-客服部 | D15: 118776.98 | E15: 8 | F15: 81373.35 | G15: 1573.67 | H15: 22030.9 | I15: 12495.5 | K15: -5116.48 | L15: 0 | N15: 1303.56 | O15: 8750
C16: Shaun-外地 | D16: 62095.51 | E16: 8 | F16: 44096 | G16: 727.19 | H16: 10282.71 | I16: 5831.61 | K16: 1002.8 | L16: 0 | N16: 1158 | O16: 3600
C17: Shaun-雇员服务部 | D17: 40595.3 | E17: 3 | F17: 25561.32 | G17: 936.04 | H17: 8668.34 | I17: 4850.6 | K17: 0 | L17: -331.04 | N17: 579 | O17: 3750
C18: HRO服务-公司销售部 | D18: 4519.83 | E18: 1 | F18: 0 | G18: 0 | H18: 2591.17 | I18: 1448.3 | K18: 0 | L18: 0 | N18: 480.36
C19: HRO服务-代收代付残疾人 | D19: 88006.32 | E19: 16 | F19: 43640 | G19: 0 | H19: 31485.81 | I19: 12880.51 | K19: 0
B20: 公寓 | C20: 园区-公寓&企业服务部 | D20: 124104.96 | E20: 9 | F20: 79312.01 | G20: 3356.47 | H20: 26050.32 | I20: 13926.8 | K20: 9724.59 | L20: 5020.69 | N20: 1459.36 | O20: 10000
B21: 办公 | C21: 园区-商办&企业服务 | D21: 146564.93 | E21: 6 | F21: 108093.04 | G21: 9255.89 | H21: 18440.54 | I21: 9895.1 | K21: 162.57 | L21: -23519.54 | N21: 880.36 | O21: 7500
B22: 大后台 | C22: C-大后台-行政 | D22: 19128.12 | E22: 3 | F22: 15065.35 | G22: 0 | H22: 2434.22 | I22: 1300.3 | K22: -241.15 | L22: 1890 | N22: 328.25 | O22: 3750
B23: 大后台 | C23: C-大后台-法务 | D23: 46980.32 | E23: 3 | F23: 35865.48 | G23: 43.77 | H23: 6559.17 | I23: 4200.3 | K23: -1484 | L23: 0 | N23: 311.6 | O23: 2500
B24: 大后台 | C24: C-大后台-人事 | D24: 14979.67 | E24: 1 | F24: 10892.3 | G24: 187.05 | H24: 2439.22 | I24: 1305.3 | K24: -315.35 | L24: 4200 | N24: 155.8 | O24: 1250
B25: 老龙 | C25: 老龙馄饨 | D25: 28067.36 | E25: 3 | F25: 26118.8 | G25: 1948.56 | H25: 0 | I25: 0 | K25: 0 | L25: 0
B26: 物业 | C26: 物业管理部 | D26: 75536.72 | E26: 4 | F26: 56568.44 | G26: 3013.92 | H26: 9918.66 | I26: 5300.9 | K26: 19166.57 | L26: -1193.31 | N26: 734.8 | O26: 5000
B27: 物业 | C27: 物业维修部 | D27: 42808.72 | E27: 3 | F27: 29255.92 | G27: 666.28 | H27: 8091.32 | I27: 4327.8 | K27: 5900 | L27: 0 | N27: 467.4 | O27: 3750
B28: 物业 | C28: 物业保安部 | D28: 70550.79 | E28: 7 | F28: 50626.91 | G28: 1659.36 | H28: 12300.32 | I28: 5496.8 | K28: 2590.67 | L28: 2892.4 | N28: 467.4 | O28: 8750
B29: 物业 | C29: 物业保洁部 | D29: 57999.44 | E29: 15 | F29: 53381.74 | G29: 571.58 | H29: 2434.22 | I29: 1300.3 | K29: 2115 | L29: -11815.38 | N29: 311.6 | O29: 16250
B30: 物业 | C30: 物业外包保安 | D30: 260500 | E30: 25 | F30: 260500 | G30: 0 | H30: 0 | I30: 0 | K30: 500 | O30: 27500
B31: 小计 | D31: =SUM(D7:D30) -> 1646505.9 | E31: =SUM(E7:E30) -> 150 | F31: =SUM(F7:F30) -> 1276349.6 | G31: =SUM(G7:G30) -> 35396.51 | H31: =SUM(H7:H30) -> 211592.29 | I31: =SUM(I7:I30) -> 111571.42 | J31: =SUM(J7:J30) -> 0 | K31: =SUM(K7:K30) -> 42176.5 | L31: =SUM(L7:L30) -> -17927.45 | N31: =SUM(N7:N30) -> 11596.06 | O31: =SUM(O7:O30) -> 123600
C37: 发薪公司 | D37: 企业人力成本总计 | F37: 实收工资 | G37: 个人所得税 | H37: 法定社会保险 （公司成本） | I37: 法定社会保险 （代扣个人） | K37: 绩效&佣金合计&津贴 | L37: 已包含 考勤调整 | N37: 商业保险（公司成本） | O37: 预提福利费
B38: 开弈人才系 | C38: 开弈信息 | D38: 164593.77 | E38: 8 | F38: 105320.53 | G38: 6056.12 | H38: 34497.66 | I38: 17415.9 | K38: -2407.45 | L38: 4200 | N38: 1303.56 | O38: 8750
C39: 开弈中国 | D39: 166656.05 | E39: 5 | F39: 157556.05 | H39: 4550 | I39: 4550 | K39: -742 | L39: 0
C40: 开弈中国-美元 | D40: 2200 | E40: 1 | F40: 2200 | H40: 0 | K40: 0 | L40: 2200
C41: 开弈人才 | D41: 21444.13 | E41: 3 | F41: 10233.62 | G41: 81.94 | H41: 6960.51 | I41: 3531.9 | K41: 0 | L41: -124.14 | N41: 636.16 | O41: 1250
C42: 开弈人力资源 | D42: 231081.36 | E42: 23 | F42: 147096.51 | G42: 5967.81 | H42: 50650.72 | I42: 25470.8 | K42: 6141.52 | L42: 0 | N42: 1895.52 | O42: 10000
C43: 开弈企业外包 | D43: 6449.47 | E43: 2 | F43: 3700 | G43: 40 | H43: 1926.17 | I43: 783.3 | K43: 0
C44: 靠普人力 | D44: 32309.51 | E44: 4 | F44: 20884.45 | G44: 179.05 | H44: 7181.51 | I44: 3752.9 | K44: 0 | L44: -206.9 | N44: 311.6 | O44: 2500
C45: 开博人才 | D45: 1000 | E45: 1 | F45: 960 | G45: 40 | H45: 0 | I45: 0 | K45: 0
C46: 弈享天津 | D46: 2000 | E46: 2 | F46: 1920 | G46: 80 | H46: 0 | I46: 0 | K46: 0 | L46: 0
...

Sheet 薪酬明细
B1: 薪资汇总表 | F1: 审核时间 | K1: 考勤统计表 | N1: a1 | O1: 基本薪资: | P1: 求职申请表（劳动劳务合同）、员工流动表；a1'待完成手续； | AB1: 本月工资： | AC1: 计税部分合计 | AE1: 组织管理 | AI1: 人事档案&人事信息统计表 | AN1: 执行责任人 | BN1: 员工福利
B2: -时期 | C2: 2026/6/1-2026/6/30 | K2: -考勤周期 | L2: 2026/6/1-2026/6/30 | N2: a2 | O2: 考勤调整： | P2: 调整天数来自考勤统计表； | AB2: KPI： | AC2: KPI | AE2: -人事任命书 | AI2: -人事信息统计表 | AN2: ✅ | AO2: 发薪 | AP2: 黄欢欢 | BN2: 行业保险补充医疗
B3: -考勤责任人 | C3: 黄燕婷 | F3: 2日发出 | K3: -考勤制表 | L3: 黄燕婷 | N3: a3 | O3: 高温费： | P3: 根据当地政策；含天津历史遗留问题； | AB3: 离职补偿金/年终奖金： | AC3: 根据离职解除协议约定/年终奖公司核算审批额 | AE3: -部门架构发起 | AI3: -薪酬工资表 | AN3: ✅ | AO3: 报税 | AP3: 黄欢欢 | AY3: =AY4-AY5 -> 0 | BN3: 高管健康管理保险
B4: -HR责任人 | C4: 黄一萧 | F4: 3日发出 | K4: -HR审核人 | L4: 黄一萧 | N4: a4 | O4: 补差补扣： | P4: HR与员工签订申请合约所约定委托代扣部分； | AB4: 特殊员工发： | AC4: 开弈人才报销通道发放 | AE4: -组织架构图 | AI4: -人事档案管理 | AN4: ✅ | AO4: 工资单 | AP4: 黄欢欢 | AY4: 35396.51 | BN4: 节日津贴（端午/中秋/春节年会/三八/六一）
B5: -公司终审批人 | C5: 张毅 | F5: 收到文件+2工作日 | N5: a61 | O5: KPI预提： | P5: KPI部分预提，KPI结算时减除； | AB5: 薪资小计： | AC5: 本月薪资汇总 | AE5: -相关内部合规审批权限表统筹管理 | AI5: -人事档案薪酬数据文档抄送 | AN5: ✅ | AO5: 社保/公积金 | AP5: 黄欢欢 | AY5: =AY161 -> 35396.51 | BN5: 生日/婚丧孕
B6: -发放工资单 | C6: 黄欢欢验证工资数据源文件代发工资单 | F6: 3个工作日 | AE6: -相关信息通知到各个部门 | AN6: ✅ | AO6: 福利费申请 | AP6: 黄燕婷 | BN6: 特殊帮助福利
K8: a+e+f | L8: d=a-b-c-c1+sum(g) | O8: a1 | P8: a1' | Q8: a2 | R8: a5 | S8: a6 | T8: a61 | U8: a0=sum(a1..a61) | V8: a75 | AC8: a=sum（a71..a8) | AH8: b1 | AI8: b2 | AJ8: b3 | AK8: b4 | AL8: b5 | AM8: b=sum(b1..b5) | AS8: a0-b | AX8: c1 | AY8: c | AZ8: g1 | BA8: g2 | BB8: h=a0-b-c-c1+sum(g)+f2 | BC8: a8 | BD8: d=a-b-c-c1+sum(g)+f2 | BE8: e1 | BF8: e2 | BG8: e3 | BH8: e4 | BI8: e5 | BJ8: e6 | BK8: e7 | BL8: e=sum(e1..e7) | BN8: f1 | BO8: f2 | BP8: f3 | BQ8: f4 | BR8: f=sum(f1:f4)
A9: 发薪公司验证数据 | B9: 成本中心（P&L核算标准） | C9: 发薪公司 | D9: 人员性质 | E9: 部门 | F9: 汇报人 | G9: 职位 | H9: 所属人 | I9: 姓名 | J9: 考勤制 | K9: 企业人力成本总计 | L9: 实收 | M9: 1 | N9: 计税月份 | O9: 基本工资 | P9: 补贴/补充公积金 | Q9: 考勤调整 | R9: 其他补贴/调整 | S9: 商保金额 | T9: KPI预提 | U9: 本月工资 | V9: 商办佣金 | W9: 绩效 | X9: 公寓佣金 | Y9: 防暑降温费 | Z9: 津贴 | AA9: 保安奖金 | AB9: 保洁奖金 | AC9: 薪资小计 | AD9: 0 | AE9: 社保公积金 缴纳月份 | AF9: 社保基数 | AG9: 公积金基数 | AH9: 养老 | AI9: 医疗 | AJ9: 失业 | AK9: 公积金 | AL9: 补充公积金 | AM9: 个人福利合计 | AN9: 累计子女教育 | AO9: 累计住房贷款利息 | AP9: 累计住房租金 | AQ9: 累计赡养老人 | AR9: 累计继续教育 | AS9: 本期纳税工资 | AT9: 1 | AU9: 累计收入 | AV9: 应纳税所得额 | AW9: 累计已扣税额 | AX9: 上月个税调整 | AY9: 当月个人所得税 | AZ9: 商保调整 | BA9: 个税调整 | BB9: 银行实发 | BC9: 账外实发 | BD9: 实收工资 | BE9: 养老 | BF9: 医疗 | BG9: 失业 | BH9: 工伤 | BI9: 生育 | BJ9: 公积金 | BK9: 补充公积金 | BL9: 公司法定福利合计 | BM9: 2 | BN9: 商业保险 | BO9: 生日/婚丧孕 | BP9: 健康管理服务费 | BQ9: 住房津贴 | BR9: 福利合计 | BS9: 绩效&佣金合计 | BT9: 预提福利费 | BU9: 富平99号项目福利费 | BV9: 备注 | BW9: 发薪公司&姓名 | BX9: 备注 | BY9: 商保 | BZ9: 比例 | CA9: 累积验证 | CB9: 发薪公司验证数据 | CC9: 商保筛选 | CD9: 所属人-姓名
A10: =C10&I10 -> 北京点才孟庆芳 | B10: Shaun-外地 | C10: 北京点才 | D10: 正常计税 | E10: 北京事业部 | F10: 杨崴 | G10: 客服专员 | H10: 孟庆芳 | I10: 孟庆芳 | J10: 全日制 | K10: =AC10+BL10 -> 1600 | L10: =AC10-AM10-AX10-AY10+SUM(AZ10:BA10) -> 1600 | N10: 6 | O10: 1600 | Q10: =VLOOKUP(I10,考勤调整记录!I:W,15,0) -> 0 | U10: =SUM(O10:T10) -> 1600 | AC10: =SUM(O10:T10)+SUM(V10:AB10) -> 1600 | AE10: 202606 | AF10: =VLOOKUP(BW10,'HR|社保明细'!C:F,4,0) -> 0 | AG10: =VLOOKUP($BW10,'HR|社保明细'!$C:G,5,0) -> 0 | AH10: =VLOOKUP($BW10,'HR|社保明细'!$C:H,6,0) -> 0 | AI10: =VLOOKUP($BW10,'HR|社保明细'!$C:I,7,0) -> 0 | AJ10: =VLOOKUP($BW10,'HR|社保明细'!$C:J,8,0) -> 0 | AK10: =VLOOKUP($BW10,'HR|社保明细'!$C:K,9,0) -> 0 | AL10: =VLOOKUP($BW10,'HR|社保明细'!$C:L,10,0) -> 0 | AM10: =SUM(AH10:AL10) -> 0 | AS10: =AC10-AM10-SUM(AN10:AR10) -> 1600 | AU10: =VLOOKUP(BW10,hr.个税累计数据!C:DS,121,0) -> 9600 | AV10: =IF(AU10-5000*N10-VLOOKUP(A10,hr.个税累计数据!C:DT,122,0)-VLOOKUP(A10,hr.个税累计数据!C:DU,123,0)>0,AU10-5000*N10-VLOOKUP(A10,hr.个税累计数据!C:DT,122,0)-VLOOKUP(A10,hr.个税累计数据!C:DU,123,0),0) -> 0 | AW10: =VLOOKUP(BW10,hr.个税累计数据!C:DV,124,0) -> 0 | AY10: =IF(ROUND(MAX(AV10*{0.03,0.1,0.2,0.25,0.3,0.35,0.45}-{0,210,1410,2660,4410,7160,15160}*12)-AW10,2)<=0,0,ROUND(MAX(AV10*{0.03,0.1,0.2,0.25,0.3,0.35,0.45}-{0,210,1410,2660,4410,7160,15160}*12)-AW10,2)) -> 0 | AZ10: =-S10 -> 0 | BB10: =AC10-AM10-AY10-AX10+SUM(AZ10:BA10) -> 1600 | BD10: =AC10-AM10-AX10-AY10+SUM(AZ10:BA10) -> 1600 | BE10: =VLOOKUP($BW10,'HR|社保明细'!C:T,11,0) -> 0 | BF10: =VLOOKUP($BW10,'HR|社保明细'!$C:U,12,0) -> 0 | BG10: =VLOOKUP($BW10,'HR|社保明细'!$C:V,13,0) -> 0 | BH10: =VLOOKUP($BW10,'HR|社保明细'!$C:W,14,0) -> 0 | BI10: =VLOOKUP($BW10,'HR|社保明细'!$C:X,15,0) -> 0 | BJ10: =VLOOKUP($BW10,'HR|社保明细'!$C:Y,16,0) -> 0 | BK10: =VLOOKUP($BW10,'HR|社保明细'!$C:Z,17,0) -> 0 | BL10: =SUM(BE10:BK10) -> 0 | BR10: =SUM(BN10:BQ10) -> 0 | BS10: =SUM(V10:AB10) -> 0 | BW10: =C10&I10 -> 北京点才孟庆芳 | BX10: 无社公 | BY10: 无 | CA10: =VLOOKUP(A10,hr.个税累计数据!C:C,1,0) -> 北京点才孟庆芳 | CB10: 北京点才孟庆芳 | CD10: =H10=I10 -> TRUE
A11: =C11&I11 -> 北京点才尚庆军 | B11: HRO服务-代收代付残疾人 | C11: 北京点才 | D11: 正常计税 | E11: 客户残疾人 | F11: 葛豪平 | G11: 残疾人 | H11: 尚庆军 | I11: 尚庆军 | J11: 代收代付残疾人 | K11: =AC11+BL11 -> 5512.27 | L11: =AC11-AM11-AX11-AY11+SUM(AZ11:BA11) -> 2540 | N11: 6 | O11: =3199.21+167.4-71.6 -> 3295.01 | U11: =SUM(O11:T11) -> 3295.01 | AC11: =SUM(O11:T11)+SUM(V11:AB11) -> 3295.01 | AE11: 202606 | AF11: =VLOOKUP(BW11,'HR|社保明细'!C:F,4,0) -> 7162 | AG11: =VLOOKUP($BW11,'HR|社保明细'!$C:G,5,0) -> 2540 | AH11: =VLOOKUP($BW11,'HR|社保明细'!$C:H,6,0) -> 572.96 | AI11: =VLOOKUP($BW11,'HR|社保明细'!$C:I,7,0) -> 146.24 | AJ11: =VLOOKUP($BW11,'HR|社保明细'!$C:J,8,0) -> 35.81 | AK11: =VLOOKUP($BW11,'HR|社保明细'!$C:K,9,0) -> 0 | AL11: =VLOOKUP($BW11,'HR|社保明细'!$C:L,10,0) -> 0 | AM11: =SUM(AH11:AL11) -> 755.01 | AS11: =AC11-AM11-SUM(AN11:AR11) -> 2540 | AU11: =VLOOKUP(BW11,hr.个税累计数据!C:DS,121,0) -> 19770.06 | AV11: =IF(AU11-5000*N11-VLOOKUP(A11,hr.个税累计数据!C:DT,122,0)-VLOOKUP(A11,hr.个税累计数据!C:DU,123,0)>0,AU11-5000*N11-VLOOKUP(A11,hr.个税累计数据!C:DT,122,0)-VLOOKUP(A11,hr.个税累计数据!C:DU,123,0),0) -> 0 | AW11: =VLOOKUP(BW11,hr.个税累计数据!C:DV,124,0) -> 0 | AY11: =IF(ROUND(MAX(AV11*{0.03,0.1,0.2,0.25,0.3,0.35,0.45}-{0,210,1410,2660,4410,7160,15160}*12)-AW11,2)<=0,0,ROUND(MAX(AV11*{0.03,0.1,0.2,0.25,0.3,0.35,0.45}-{0,210,1410,2660,4410,7160,15160}*12)-AW11,2)) -> 0 | AZ11: =-S11 -> 0 | BB11: =AC11-AM11-AY11-AX11+SUM(AZ11:BA11) -> 2540 | BD11: =AC11-AM11-AX11-AY11+SUM(AZ11:BA11) -> 2540 | BE11: =VLOOKUP($BW11,'HR|社保明细'!C:T,11,0) -> 1145.92 | BF11: =VLOOKUP($BW11,'HR|社保明细'!$C:U,12,0) -> 644.58 | BG11: =VLOOKUP($BW11,'HR|社保明细'!$C:V,13,0) -> 35.81 | BH11: =VLOOKUP($BW11,'HR|社保明细'!$C:W,14,0) -> 28.65 | BI11: =VLOOKUP($BW11,'HR|社保明细'!$C:X,15,0) -> 57.3 | BJ11: =VLOOKUP($BW11,'HR|社保明细'!$C:Y,16,0) -> 305 | BK11: =VLOOKUP($BW11,'HR|社保明细'!$C:Z,17,0) -> 0 | BL11: =SUM(BE11:BK11) -> 2217.26 | BR11: =SUM(BN11:BQ11) -> 0 | BS11: =SUM(V11:AB11) -> 0 | BW11: =C11&I11 -> 北京点才尚庆军 | BY11: 无 | CA11: =VLOOKUP(A11,hr.个税累计数据!C:C,1,0) -> 北京点才尚庆军 | CB11: 北京点才尚庆军 | CD11: =H11=I11 -> TRUE
A12: =C12&I12 -> 北京点才王倩 | B12: 公司费用-待结算&法人&智名 | C12: 北京点才 | D12: 劳务计税 | E12: 公司费用-法人 | F12: 张毅 | G12: 法人 | H12: 王倩 | I12: 王倩 | J12: 非全日制 | K12: =AC12+BL12 -> 1000 | L12: =AC12-AM12-AX12-AY12+SUM(AZ12:BA12) -> 960 | N12: 6 | O12: 1000 | U12: =SUM(O12:T12) -> 1000 | AC12: =SUM(O12:T12)+SUM(V12:AB12) -> 1000 | AE12: 202606 | AF12: =VLOOKUP(BW12,'HR|社保明细'!C:F,4,0) -> 0 | AG12: =VLOOKUP($BW12,'HR|社保明细'!$C:G,5,0) -> 0 | AH12: =VLOOKUP($BW12,'HR|社保明细'!$C:H,6,0) -> 0 | AI12: =VLOOKUP($BW12,'HR|社保明细'!$C:I,7,0) -> 0 | AJ12: =VLOOKUP($BW12,'HR|社保明细'!$C:J,8,0) -> 0 | AK12: =VLOOKUP($BW12,'HR|社保明细'!$C:K,9,0) -> 0 | AL12: =VLOOKUP($BW12,'HR|社保明细'!$C:L,10,0) -> 0 | AM12: =SUM(AH12:AL12) -> 0 | AS12: 1000 | AU12: =VLOOKUP(BW12,hr.个税累计数据!C:DS,121,0) -> 6000 | AV12: =IF(AU12-5000*N12-VLOOKUP(A12,hr.个税累计数据!C:DT,122,0)-VLOOKUP(A12,hr.个税累计数据!C:DU,123,0)>0,AU12-5000*N12-VLOOKUP(A12,hr.个税累计数据!C:DT,122,0)-VLOOKUP(A12,hr.个税累计数据!C:DU,123,0),0) -> 0 | AW12: =VLOOKUP(BW12,hr.个税累计数据!C:DV,124,0) -> 200 | AY12: =IF(D12="国内不计税",0,IF(D12="正常计税",ROUND(MAX(AS12*{0.03,0.1,0.2,0.25,0.3,0.35,0.45}-{0,210,1410,2660,4410,7160,15160},0),2),IF(D12="外籍人",ROUND(MAX(AS12*{0.03,0.1,0.2,0.25,0.3,0.35,0.45}-{0,210,1410,2660,4410,7160,15160},0),2),ROUND(MAX((AS12-IF(AS12<4000,800,AS12*0.2))*10%*{2,3,4}-1000*{0,2,7},0),2)))) -> 40 | AZ12: =-S12 -> 0 | BB12: =AC12-AM12-AY12-AX12+SUM(AZ12:BA12) -> 960 | BD12: =AC12-AM12-AX12-AY12+SUM(AZ12:BA12) -> 960 | BE12: =VLOOKUP($BW12,'HR|社保明细'!C:T,11,0) -> 0 | BF12: =VLOOKUP($BW12,'HR|社保明细'!$C:U,12,0) -> 0 | BG12: =VLOOKUP($BW12,'HR|社保明细'!$C:V,13,0) -> 0 | BH12: =VLOOKUP($BW12,'HR|社保明细'!$C:W,14,0) -> 0 | BI12: =VLOOKUP($BW12,'HR|社保明细'!$C:X,15,0) -> 0 | BJ12: =VLOOKUP($BW12,'HR|社保明细'!$C:Y,16,0) -> 0 | BK12: =VLOOKUP($BW12,'HR|社保明细'!$C:Z,17,0) -> 0 | BL12: =SUM(BE12:BK12) -> 0 | BR12: =SUM(BN12:BQ12) -> 0 | BS12: =SUM(V12:AB12) -> 0 | BW12: =C12&I12 -> 北京点才王倩 | BX12: 无社公 | BY12: 无 | CA12: =VLOOKUP(A12,hr.个税累计数据!C:C,1,0) -> 北京点才王倩 | CB12: 北京点才王倩 | CD12: =H12=I12 -> TRUE
A13: =C13&I13 -> 北京点才杨崴 | B13: Shaun-外地 | C13: 北京点才 | D13: 正常计税 | E13: 北京事业部 | F13: 黄一萧 | G13: 客服专员 | H13: 杨崴 | I13: 杨崴 | J13: 全日制 | K13: =AC13+BL13 -> 11019.66 | L13: =AC13-AM13-AX13-AY13+SUM(AZ13:BA13) -> 6404.99 | N13: 6 | O13: 8000 | Q13: =VLOOKUP(I13,考勤调整记录!I:W,15,0) -> 0 | S13: 267.4 | U13: =SUM(O13:T13) -> 8267.4 | AC13: =SUM(O13:T13)+SUM(V13:AB13) -> 8267.4 | AE13: 202606 | AF13: =VLOOKUP(BW13,'HR|社保明细'!C:F,4,0) -> 7162 | AG13: =VLOOKUP($BW13,'HR|社保明细'!$C:G,5,0) -> 7000 | AH13: =VLOOKUP($BW13,'HR|社保明细'!$C:H,6,0) -> 572.96 | AI13: =VLOOKUP($BW13,'HR|社保明细'!$C:I,7,0) -> 146.24 | AJ13: =VLOOKUP($BW13,'HR|社保明细'!$C:J,8,0) -> 35.81 | AK13: =VLOOKUP($BW13,'HR|社保明细'!$C:K,9,0) -> 840 | AL13: =VLOOKUP($BW13,'HR|社保明细'!$C:L,10,0) -> 0 | AM13: =SUM(AH13:AL13) -> 1595.01 | AS13: =AC13-AM13-SUM(AN13:AR13) -> 6672.39 | AU13: =VLOOKUP(BW13,hr.个税累计数据!C:DS,121,0) -> 48849.15 | AV13: =IF(AU13-5000*N13-VLOOKUP(A13,hr.个税累计数据!C:DT,122,0)-VLOOKUP(A13,hr.个税累计数据!C:DU,123,0)>0,AU13-5000*N13-VLOOKUP(A13,hr.个税累计数据!C:DT,122,0)-VLOOKUP(A13,hr.个税累计数据!C:DU,123,0),0) -> 0 | AW13: =VLOOKUP(BW13,hr.个税累计数据!C:DV,124,0) -> 0 | AY13: =IF(ROUND(MAX(AV13*{0.03,0.1,0.2,0.25,0.3,0.35,0.45}-{0,210,1410,2660,4410,7160,15160}*12)-AW13,2)<=0,0,ROUND(MAX(AV13*{0.03,0.1,0.2,0.25,0.3,0.35,0.45}-{0,210,1410,2660,4410,7160,15160}*12)-AW13,2)) -> 0 | AZ13: =-S13 -> -267.4 | BB13: =AC13-AM13-AY13-AX13+SUM(AZ13:BA13) -> 6404.99 | BD13: =AC13-AM13-AX13-AY13+SUM(AZ13:BA13) -> 6404.99 | BE13: =VLOOKUP($BW13,'HR|社保明细'!C:T,11,0) -> 1145.92 | BF13: =VLOOKUP($BW13,'HR|社保明细'!$C:U,12,0) -> 644.58 | BG13: =VLOOKUP($BW13,'HR|社保明细'!$C:V,13,0) -> 35.81 | BH13: =VLOOKUP($BW13,'HR|社保明细'!$C:W,14,0) -> 28.65 | BI13: =VLOOKUP($BW13,'HR|社保明细'!$C:X,15,0) -> 57.3 | BJ13: =VLOOKUP($BW13,'HR|社保明细'!$C:Y,16,0) -> 840 | BK13: =VLOOKUP($BW13,'HR|社保明细'!$C:Z,17,0) -> 0 | BL13: =SUM(BE13:BK13) -> 2752.26 | BR13: =SUM(BN13:BQ13) -> 0 | BS13: =SUM(V13:AB13) -> 0 | BT13: 600 | BW13: =C13&I13 -> 北京点才杨崴 | BY13: 有 | BZ13: 人才 | CA13: =VLOOKUP(A13,hr.个税累计数据!C:C,1,0) -> 北京点才杨崴 | CB13: 北京点才杨崴 | CC13: 有 | CD13: =H13=I13 -> TRUE
A14: =C14&I14 -> 开博人才王倩 | B14: 公司费用-待结算&法人&智名 | C14: 开博人才 | D14: 劳务计税 | E14: 公司费用-法人 | F14: 张毅 | G14: 法人 | H14: 王倩 | I14: 王倩 | J14: 非全日制 | K14: =AC14+BL14 -> 1000 | L14: =AC14-AM14-AX14-AY14+SUM(AZ14:BA14) -> 960 | N14: 6 | O14: 1000 | U14: =SUM(O14:T14) -> 1000 | AC14: =SUM(O14:T14)+SUM(V14:AB14) -> 1000 | AE14: 202606 | AF14: =VLOOKUP(BW14,'HR|社保明细'!C:F,4,0) -> 0 | AG14: =VLOOKUP($BW14,'HR|社保明细'!$C:G,5,0) -> 0 | AH14: =VLOOKUP($BW14,'HR|社保明细'!$C:H,6,0) -> 0 | AI14: =VLOOKUP($BW14,'HR|社保明细'!$C:I,7,0) -> 0 | AJ14: =VLOOKUP($BW14,'HR|社保明细'!$C:J,8,0) -> 0 | AK14: =VLOOKUP($BW14,'HR|社保明细'!$C:K,9,0) -> 0 | AL14: =VLOOKUP($BW14,'HR|社保明细'!$C:L,10,0) -> 0 | AM14: =SUM(AH14:AL14) -> 0 | AS14: 1000 | AU14: =VLOOKUP(BW14,hr.个税累计数据!C:DS,121,0) -> 6000 | AV14: =IF(AU14-5000*N14-VLOOKUP(A14,hr.个税累计数据!C:DT,122,0)-VLOOKUP(A14,hr.个税累计数据!C:DU,123,0)>0,AU14-5000*N14-VLOOKUP(A14,hr.个税累计数据!C:DT,122,0)-VLOOKUP(A14,hr.个税累计数据!C:DU,123,0),0) -> 0 | AW14: =VLOOKUP(BW14,hr.个税累计数据!C:DV,124,0) -> 200 | AY14: =IF(D14="国内不计税",0,IF(D14="正常计税",ROUND(MAX(AS14*{0.03,0.1,0.2,0.25,0.3,0.35,0.45}-{0,210,1410,2660,4410,7160,15160},0),2),IF(D14="外籍人",ROUND(MAX(AS14*{0.03,0.1,0.2,0.25,0.3,0.35,0.45}-{0,210,1410,2660,4410,7160,15160},0),2),ROUND(MAX((AS14-IF(AS14<4000,800,AS14*0.2))*10%*{2,3,4}-1000*{0,2,7},0),2)))) -> 40 | AZ14: =-S14 -> 0 | BB14: =AC14-AM14-AY14-AX14+SUM(AZ14:BA14) -> 960 | BD14: =AC14-AM14-AX14-AY14+SUM(AZ14:BA14) -> 960 | BE14: =VLOOKUP($BW14,'HR|社保明细'!C:T,11,0) -> 0 | BF14: =VLOOKUP($BW14,'HR|社保明细'!$C:U,12,0) -> 0 | BG14: =VLOOKUP($BW14,'HR|社保明细'!$C:V,13,0) -> 0 | BH14: =VLOOKUP($BW14,'HR|社保明细'!$C:W,14,0) -> 0 | BI14: =VLOOKUP($BW14,'HR|社保明细'!$C:X,15,0) -> 0 | BJ14: =VLOOKUP($BW14,'HR|社保明细'!$C:Y,16,0) -> 0 | BK14: =VLOOKUP($BW14,'HR|社保明细'!$C:Z,17,0) -> 0 | BL14: =SUM(BE14:BK14) -> 0 | BR14: =SUM(BN14:BQ14) -> 0 | BS14: =SUM(V14:AB14) -> 0 | BW14: =C14&I14 -> 开博人才王倩 | BX14: 无社公 | BY14: 无 | CA14: =VLOOKUP(A14,hr.个税累计数据!C:C,1,0) -> 开博人才王倩 | CB14: 开博人才王倩 | CD14: =H14=I14 -> TRUE
A15: =C15&I15 -> 开弈企业外包吴玉斌 | B15: HRO服务-代收代付残疾人 | C15: 开弈企业外包 | D15: 正常计税 | E15: 客户残疾人 | F15: 葛豪平 | G15: 残疾人 | H15: 吴玉斌 | I15: 吴玉斌 | J15: 代收代付残疾人 | K15: =AC15+BL15 -> 5449.47 | L15: =AC15-AM15-AX15-AY15+SUM(AZ15:BA15) -> 2740 | N15: 6 | O15: =3457.55+15.54-7.77+50+23.94-15.96 -> 3523.3 | U15: =SUM(O15:T15) -> 3523.3 | AC15: =SUM(O15:T15)+SUM(V15:AB15) -> 3523.3 | AE15: 202606 | AF15: =VLOOKUP(BW15,'HR|社保明细'!C:F,4,0) -> 7460 | AG15: =VLOOKUP($BW15,'HR|社保明细'!$C:G,5,0) -> 0 | AH15: =VLOOKUP($BW15,'HR|社保明细'!$C:H,6,0) -> 596.8 | AI15: =VLOOKUP($BW15,'HR|社保明细'!$C:I,7,0) -> 149.2 | AJ15: =VLOOKUP($BW15,'HR|社保明细'!$C:J,8,0) -> 37.3 | AK15: =VLOOKUP($BW15,'HR|社保明细'!$C:K,9,0) -> 0 | AL15: =VLOOKUP($BW15,'HR|社保明细'!$C:L,10,0) -> 0 | AM15: =SUM(AH15:AL15) -> 783.3 | AS15: =AC15-AM15-SUM(AN15:AR15) -> 2740 | AU15: =VLOOKUP(BW15,hr.个税累计数据!C:DS,121,0) -> 21139.8 | AV15: =IF(AU15-5000*N15-VLOOKUP(A15,hr.个税累计数据!C:DT,122,0)-VLOOKUP(A15,hr.个税累计数据!C:DU,123,0)>0,AU15-5000*N15-VLOOKUP(A15,hr.个税累计数据!C:DT,122,0)-VLOOKUP(A15,hr.个税累计数据!C:DU,123,0),0) -> 0 | AW15: =VLOOKUP(BW15,hr.个税累计数据!C:DV,124,0) -> 0 | AY15: =IF(ROUND(MAX(AV15*{0.03,0.1,0.2,0.25,0.3,0.35,0.45}-{0,210,1410,2660,4410,7160,15160}*12)-AW15,2)<=0,0,ROUND(MAX(AV15*{0.03,0.1,0.2,0.25,0.3,0.35,0.45}-{0,210,1410,2660,4410,7160,15160}*12)-AW15,2)) -> 0 | AZ15: =-S15 -> 0 | BB15: =AC15-AM15-AY15-AX15+SUM(AZ15:BA15) -> 2740 | BD15: =AC15-AM15-AX15-AY15+SUM(AZ15:BA15) -> 2740 | BE15: =VLOOKUP($BW15,'HR|社保明细'!C:T,11,0) -> 1193.6 | BF15: =VLOOKUP($BW15,'HR|社保明细'!$C:U,12,0) -> 596.8 | BG15: =VLOOKUP($BW15,'HR|社保明细'!$C:V,13,0) -> 37.3 | BH15: =VLOOKUP($BW15,'HR|社保明细'!$C:W,14,0) -> 23.87 | BI15: =VLOOKUP($BW15,'HR|社保明细'!$C:X,15,0) -> 74.6 | BJ15: =VLOOKUP($BW15,'HR|社保明细'!$C:Y,16,0) -> 0 | BK15: =VLOOKUP($BW15,'HR|社保明细'!$C:Z,17,0) -> 0 | BL15: =SUM(BE15:BK15) -> 1926.17 | BR15: =SUM(BN15:BQ15) -> 0 | BS15: =SUM(V15:AB15) -> 0 | BW15: =C15&I15 -> 开弈企业外包吴玉斌 | BY15: 无 | CA15: =VLOOKUP(A15,hr.个税累计数据!C:C,1,0) -> 开弈企业外包吴玉斌 | CB15: 开弈人力资源吴玉斌 | CD15: =H15=I15 -> TRUE
A16: =C16&I16 -> 开弈企业外包王倩 | B16: 公司费用-待结算&法人&智名 | C16: 开弈企业外包 | D16: 劳务计税 | E16: 公司费用-法人 | F16: 张毅 | G16: 法人 | H16: 王倩 | I16: 王倩 | J16: 非全日制 | K16: =AC16+BL16 -> 1000 | L16: =AC16-AM16-AX16-AY16+SUM(AZ16:BA16) -> 960 | N16: 6 | O16: 1000 | U16: =SUM(O16:T16) -> 1000 | AC16: =SUM(O16:T16)+SUM(V16:AB16) -> 1000 | AE16: 202606 | AF16: =VLOOKUP(BW16,'HR|社保明细'!C:F,4,0) -> 0 | AG16: =VLOOKUP($BW16,'HR|社保明细'!$C:G,5,0) -> 0 | AH16: =VLOOKUP($BW16,'HR|社保明细'!$C:H,6,0) -> 0 | AI16: =VLOOKUP($BW16,'HR|社保明细'!$C:I,7,0) -> 0 | AJ16: =VLOOKUP($BW16,'HR|社保明细'!$C:J,8,0) -> 0 | AK16: =VLOOKUP($BW16,'HR|社保明细'!$C:K,9,0) -> 0 | AL16: =VLOOKUP($BW16,'HR|社保明细'!$C:L,10,0) -> 0 | AM16: =SUM(AH16:AL16) -> 0 | AS16: 1000 | AU16: =VLOOKUP(BW16,hr.个税累计数据!C:DS,121,0) -> 6000 | AV16: =IF(AU16-5000*N16-VLOOKUP(A16,hr.个税累计数据!C:DT,122,0)-VLOOKUP(A16,hr.个税累计数据!C:DU,123,0)>0,AU16-5000*N16-VLOOKUP(A16,hr.个税累计数据!C:DT,122,0)-VLOOKUP(A16,hr.个税累计数据!C:DU,123,0),0) -> 0 | AW16: =VLOOKUP(BW16,hr.个税累计数据!C:DV,124,0) -> 200 | AY16: =IF(D16="国内不计税",0,IF(D16="正常计税",ROUND(MAX(AS16*{0.03,0.1,0.2,0.25,0.3,0.35,0.45}-{0,210,1410,2660,4410,7160,15160},0),2),IF(D16="外籍人",ROUND(MAX(AS16*{0.03,0.1,0.2,0.25,0.3,0.35,0.45}-{0,210,1410,2660,4410,7160,15160},0),2),ROUND(MAX((AS16-IF(AS16<4000,800,AS16*0.2))*10%*{2,3,4}-1000*{0,2,7},0),2)))) -> 40 | AZ16: =-S16 -> 0 | BB16: =AC16-AM16-AY16-AX16+SUM(AZ16:BA16) -> 960 | BD16: =AC16-AM16-AX16-AY16+SUM(AZ16:BA16) -> 960 | BE16: =VLOOKUP($BW16,'HR|社保明细'!C:T,11,0) -> 0 | BF16: =VLOOKUP($BW16,'HR|社保明细'!$C:U,12,0) -> 0 | BG16: =VLOOKUP($BW16,'HR|社保明细'!$C:V,13,0) -> 0 | BH16: =VLOOKUP($BW16,'HR|社保明细'!$C:W,14,0) -> 0 | BI16: =VLOOKUP($BW16,'HR|社保明细'!$C:X,15,0) -> 0 | BJ16: =VLOOKUP($BW16,'HR|社保明细'!$C:Y,16,0) -> 0 | BK16: =VLOOKUP($BW16,'HR|社保明细'!$C:Z,17,0) -> 0 | BL16: =SUM(BE16:BK16) -> 0 | BR16: =SUM(BN16:BQ16) -> 0 | BS16: =SUM(V16:AB16) -> 0 | BW16: =C16&I16 -> 开弈企业外包王倩 | BX16: 无社公 | BY16: 无 | CA16: =VLOOKUP(A16,hr.个税累计数据!C:C,1,0) -> 开弈企业外包王倩 | CB16: 开弈企业外包王倩 | CD16: =H16=I16 -> TRUE
A17: =C17&I17 -> 靠普人力英成盛 | B17: HRO服务-代收代付残疾人 | C17: 靠普人力 | D17: 正常计税 | E17: 客户残疾人 | F17: 葛豪平 | G17: 残疾人 | H17: 英成盛 | I17: 英成盛 | J17: 代收代付残疾人 | K17: =AC17+BL17 -> 5449.47 | L17: =AC17-AM17-AX17-AY17+SUM(AZ17:BA17) -> 2740 | N17: 6 | O17: =3457.55+15.54-7.77+50+23.94-15.96 -> 3523.3 | U17: =SUM(O17:T17) -> 3523.3 | AC17: =SUM(O17:T17)+SUM(V17:AB17) -> 3523.3 | AE17: 202606 | AF17: =VLOOKUP(BW17,'HR|社保明细'!C:F,4,0) -> 7460 | AG17: =VLOOKUP($BW17,'HR|社保明细'!$C:G,5,0) -> 0 | AH17: =VLOOKUP($BW17,'HR|社保明细'!$C:H,6,0) -> 596.8 | AI17: =VLOOKUP($BW17,'HR|社保明细'!$C:I,7,0) -> 149.2 | AJ17: =VLOOKUP($BW17,'HR|社保明细'!$C:J,8,0) -> 37.3 | AK17: =VLOOKUP($BW17,'HR|社保明细'!$C:K,9,0) -> 0 | AL17: =VLOOKUP($BW17,'HR|社保明细'!$C:L,10,0) -> 0 | AM17: =SUM(AH17:AL17) -> 783.3 | AS17: =AC17-AM17-SUM(AN17:AR17) -> 2740 | AU17: =VLOOKUP(BW17,hr.个税累计数据!C:DS,121,0) -> 21139.8 | AV17: =IF(AU17-5000*N17-VLOOKUP(A17,hr.个税累计数据!C:DT,122,0)-VLOOKUP(A17,hr.个税累计数据!C:DU,123,0)>0,AU17-5000*N17-VLOOKUP(A17,hr.个税累计数据!C:DT,122,0)-VLOOKUP(A17,hr.个税累计数据!C:DU,123,0),0) -> 0 | AW17: =VLOOKUP(BW17,hr.个税累计数据!C:DV,124,0) -> 0 | AY17: =IF(ROUND(MAX(AV17*{0.03,0.1,0.2,0.25,0.3,0.35,0.45}-{0,210,1410,2660,4410,7160,15160}*12)-AW17,2)<=0,0,ROUND(MAX(AV17*{0.03,0.1,0.2,0.25,0.3,0.35,0.45}-{0,210,1410,2660,4410,7160,15160}*12)-AW17,2)) -> 0 | AZ17: =-S17 -> 0 | BB17: =AC17-AM17-AY17-AX17+SUM(AZ17:BA17) -> 2740 | BD17: =AC17-AM17-AX17-AY17+SUM(AZ17:BA17) -> 2740 | BE17: =VLOOKUP($BW17,'HR|社保明细'!C:T,11,0) -> 1193.6 | BF17: =VLOOKUP($BW17,'HR|社保明细'!$C:U,12,0) -> 596.8 | BG17: =VLOOKUP($BW17,'HR|社保明细'!$C:V,13,0) -> 37.3 | BH17: =VLOOKUP($BW17,'HR|社保明细'!$C:W,14,0) -> 23.87 | BI17: =VLOOKUP($BW17,'HR|社保明细'!$C:X,15,0) -> 74.6 | BJ17: =VLOOKUP($BW17,'HR|社保明细'!$C:Y,16,0) -> 0 | BK17: =VLOOKUP($BW17,'HR|社保明细'!$C:Z,17,0) -> 0 | BL17: =SUM(BE17:BK17) -> 1926.17 | BR17: =SUM(BN17:BQ17) -> 0 | BS17: =SUM(V17:AB17) -> 0 | BW17: =C17&I17 -> 靠普人力英成盛 | BY17: 无 | CA17: =VLOOKUP(A17,hr.个税累计数据!C:C,1,0) -> 靠普人力英成盛 | CB17: 开弈人力资源英成盛 | CD17: =H17=I17 -> TRUE
A18: =C18&I18 -> 开弈人力资源曹保兵 | B18: HRO服务-代收代付残疾人 | C18: 开弈人力资源 | D18: 正常计税 | E18: 客户残疾人 | F18: 葛豪平 | G18: 残疾人 | H18: 曹保兵 | I18: 曹保兵 | J18: 代收代付残疾人 | K18: =AC18+BL18 -> 5449.47 | L18: =AC18-AM18-AX18-AY18+SUM(AZ18:BA18) -> 2740 | N18: 6 | O18: =3457.55+15.54-7.77+50+23.94-15.96 -> 3523.3 | U18: =SUM(O18:T18) -> 3523.3 | AC18: =SUM(O18:T18)+SUM(V18:AB18) -> 3523.3 | AE18: 202606 | AF18: =VLOOKUP(BW18,'HR|社保明细'!C:F,4,0) -> 7460 | AG18: =VLOOKUP($BW18,'HR|社保明细'!$C:G,5,0) -> 0 | AH18: =VLOOKUP($BW18,'HR|社保明细'!$C:H,6,0) -> 596.8 | AI18: =VLOOKUP($BW18,'HR|社保明细'!$C:I,7,0) -> 149.2 | AJ18: =VLOOKUP($BW18,'HR|社保明细'!$C:J,8,0) -> 37.3 | AK18: =VLOOKUP($BW18,'HR|社保明细'!$C:K,9,0) -> 0 | AL18: =VLOOKUP($BW18,'HR|社保明细'!$C:L,10,0) -> 0 | AM18: =SUM(AH18:AL18) -> 783.3 | AS18: =AC18-AM18-SUM(AN18:AR18) -> 2740 | AU18: =VLOOKUP(BW18,hr.个税累计数据!C:DS,121,0) -> 21139.8 | AV18: =IF(AU18-5000*N18-VLOOKUP(A18,hr.个税累计数据!C:DT,122,0)-VLOOKUP(A18,hr.个税累计数据!C:DU,123,0)>0,AU18-5000*N18-VLOOKUP(A18,hr.个税累计数据!C:DT,122,0)-VLOOKUP(A18,hr.个税累计数据!C:DU,123,0),0) -> 0 | AW18: =VLOOKUP(BW18,hr.个税累计数据!C:DV,124,0) -> 0 | AY18: =IF(ROUND(MAX(AV18*{0.03,0.1,0.2,0.25,0.3,0.35,0.45}-{0,210,1410,2660,4410,7160,15160}*12)-AW18,2)<=0,0,ROUND(MAX(AV18*{0.03,0.1,0.2,0.25,0.3,0.35,0.45}-{0,210,1410,2660,4410,7160,15160}*12)-AW18,2)) -> 0 | AZ18: =-S18 -> 0 | BB18: =AC18-AM18-AY18-AX18+SUM(AZ18:BA18) -> 2740 | BD18: =AC18-AM18-AX18-AY18+SUM(AZ18:BA18) -> 2740 | BE18: =VLOOKUP($BW18,'HR|社保明细'!C:T,11,0) -> 1193.6 | BF18: =VLOOKUP($BW18,'HR|社保明细'!$C:U,12,0) -> 596.8 | BG18: =VLOOKUP($BW18,'HR|社保明细'!$C:V,13,0) -> 37.3 | BH18: =VLOOKUP($BW18,'HR|社保明细'!$C:W,14,0) -> 23.87 | BI18: =VLOOKUP($BW18,'HR|社保明细'!$C:X,15,0) -> 74.6 | BJ18: =VLOOKUP($BW18,'HR|社保明细'!$C:Y,16,0) -> 0 | BK18: =VLOOKUP($BW18,'HR|社保明细'!$C:Z,17,0) -> 0 | BL18: =SUM(BE18:BK18) -> 1926.17 | BR18: =SUM(BN18:BQ18) -> 0 | BS18: =SUM(V18:AB18) -> 0 | BW18: =C18&I18 -> 开弈人力资源曹保兵 | BY18: 无 | CA18: =VLOOKUP(A18,hr.个税累计数据!C:C,1,0) -> 开弈人力资源曹保兵 | CB18: 开弈人力资源曹保兵 | CD18: =H18=I18 -> TRUE
A19: =C19&I19 -> 开弈人力资源陶桔林 | B19: HRO服务-代收代付残疾人 | C19: 开弈人力资源 | D19: 正常计税 | E19: 客户残疾人 | F19: 葛豪平 | G19: 残疾人 | H19: 陶桔林 | I19: 陶桔林 | J19: 代收代付残疾人 | K19: =AC19+BL19 -> 5825.47 | L19: =AC19-AM19-AX19-AY19+SUM(AZ19:BA19) -> 2740 | N19: 6 | O19: =3638.55+22.54-7.77+50+23.94-15.96 -> 3711.3 | U19: =SUM(O19:T19) -> 3711.3 | AC19: =SUM(O19:T19)+SUM(V19:AB19) -> 3711.3 | AE19: 202606 | AF19: =VLOOKUP(BW19,'HR|社保明细'!C:F,4,0) -> 7460 | AG19: =VLOOKUP($BW19,'HR|社保明细'!$C:G,5,0) -> 2690 | AH19: =VLOOKUP($BW19,'HR|社保明细'!$C:H,6,0) -> 596.8 | AI19: =VLOOKUP($BW19,'HR|社保明细'!$C:I,7,0) -> 149.2 | AJ19: =VLOOKUP($BW19,'HR|社保明细'!$C:J,8,0) -> 37.3 | AK19: =VLOOKUP($BW19,'HR|社保明细'!$C:K,9,0) -> 188 | AL19: =VLOOKUP($BW19,'HR|社保明细'!$C:L,10,0) -> 0 | AM19: =SUM(AH19:AL19) -> 971.3 | AS19: =AC19-AM19-SUM(AN19:AR19) -> 2740 | AU19: =VLOOKUP(BW19,hr.个税累计数据!C:DS,121,0) -> 22267.8 | AV19: =IF(AU19-5000*N19-VLOOKUP(A19,hr.个税累计数据!C:DT,122,0)-VLOOKUP(A19,hr.个税累计数据!C:DU,123,0)>0,AU19-5000*N19-VLOOKUP(A19,hr.个税累计数据!C:DT,122,0)-VLOOKUP(A19,hr.个税累计数据!C:DU,123,0),0) -> 0 | AW19: =VLOOKUP(BW19,hr.个税累计数据!C:DV,124,0) -> 0 | AY19: =IF(ROUND(MAX(AV19*{0.03,0.1,0.2,0.25,0.3,0.35,0.45}-{0,210,1410,2660,4410,7160,15160}*12)-AW19,2)<=0,0,ROUND(MAX(AV19*{0.03,0.1,0.2,0.25,0.3,0.35,0.45}-{0,210,1410,2660,4410,7160,15160}*12)-AW19,2)) -> 0 | AZ19: =-S19 -> 0 | BB19: =AC19-AM19-AY19-AX19+SUM(AZ19:BA19) -> 2740 | BD19: =AC19-AM19-AX19-AY19+SUM(AZ19:BA19) -> 2740 | BE19: =VLOOKUP($BW19,'HR|社保明细'!C:T,11,0) -> 1193.6 | BF19: =VLOOKUP($BW19,'HR|社保明细'!$C:U,12,0) -> 596.8 | BG19: =VLOOKUP($BW19,'HR|社保明细'!$C:V,13,0) -> 37.3 | BH19: =VLOOKUP($BW19,'HR|社保明细'!$C:W,14,0) -> 23.87 | BI19: =VLOOKUP($BW19,'HR|社保明细'!$C:X,15,0) -> 74.6 | BJ19: =VLOOKUP($BW19,'HR|社保明细'!$C:Y,16,0) -> 188 | BK19: =VLOOKUP($BW19,'HR|社保明细'!$C:Z,17,0) -> 0 | BL19: =SUM(BE19:BK19) -> 2114.17 | BR19: =SUM(BN19:BQ19) -> 0 | BS19: =SUM(V19:AB19) -> 0 | BW19: =C19&I19 -> 开弈人力资源陶桔林 | BY19: 无 | CA19: =VLOOKUP(A19,hr.个税累计数据!C:C,1,0) -> 开弈人力资源陶桔林 | CB19: 开弈人力资源陶桔林 | CD19: =H19=I19 -> TRUE
A20: =C20&I20 -> 开弈人力资源李晓晓 | B20: HRO服务-代收代付残疾人 | C20: 开弈人力资源 | D20: 正常计税 | E20: 客户残疾人 | F20: 葛豪平 | G20: 残疾人 | H20: 李晓晓 | I20: 李晓晓 | J20: 代收代付残疾人 | K20: =AC20+BL20 -> 5449.47 | L20: =AC20-AM20-AX20-AY20+SUM(AZ20:BA20) -> 2740 | N20: 6 | O20: =3457.55+15.54-7.77+50+23.94-15.96 -> 3523.3 | U20: =SUM(O20:T20) -> 3523.3 | AC20: =SUM(O20:T20)+SUM(V20:AB20) -> 3523.3 | AE20: 202606 | AF20: =VLOOKUP(BW20,'HR|社保明细'!C:F,4,0) -> 7460 | AG20: =VLOOKUP($BW20,'HR|社保明细'!$C:G,5,0) -> 0 | AH20: =VLOOKUP($BW20,'HR|社保明细'!$C:H,6,0) -> 596.8 | AI20: =VLOOKUP($BW20,'HR|社保明细'!$C:I,7,0) -> 149.2 | AJ20: =VLOOKUP($BW20,'HR|社保明细'!$C:J,8,0) -> 37.3 | AK20: =VLOOKUP($BW20,'HR|社保明细'!$C:K,9,0) -> 0 | AL20: =VLOOKUP($BW20,'HR|社保明细'!$C:L,10,0) -> 0 | AM20: =SUM(AH20:AL20) -> 783.3 | AS20: =AC20-AM20-SUM(AN20:AR20) -> 2740 | AU20: =VLOOKUP(BW20,hr.个税累计数据!C:DS,121,0) -> 21139.8 | AV20: =IF(AU20-5000*N20-VLOOKUP(A20,hr.个税累计数据!C:DT,122,0)-VLOOKUP(A20,hr.个税累计数据!C:DU,123,0)>0,AU20-5000*N20-VLOOKUP(A20,hr.个税累计数据!C:DT,122,0)-VLOOKUP(A20,hr.个税累计数据!C:DU,123,0),0) -> 0 | AW20: =VLOOKUP(BW20,hr.个税累计数据!C:DV,124,0) -> 0 | AY20: =IF(ROUND(MAX(AV20*{0.03,0.1,0.2,0.25,0.3,0.35,0.45}-{0,210,1410,2660,4410,7160,15160}*12)-AW20,2)<=0,0,ROUND(MAX(AV20*{0.03,0.1,0.2,0.25,0.3,0.35,0.45}-{0,210,1410,2660,4410,7160,15160}*12)-AW20,2)) -> 0 | AZ20: =-S20 -> 0 | BB20: =AC20-AM20-AY20-AX20+SUM(AZ20:BA20) -> 2740 | BD20: =AC20-AM20-AX20-AY20+SUM(AZ20:BA20) -> 2740 | BE20: =VLOOKUP($BW20,'HR|社保明细'!C:T,11,0) -> 1193.6 | BF20: =VLOOKUP($BW20,'HR|社保明细'!$C:U,12,0) -> 596.8 | BG20: =VLOOKUP($BW20,'HR|社保明细'!$C:V,13,0) -> 37.3 | BH20: =VLOOKUP($BW20,'HR|社保明细'!$C:W,14,0) -> 23.87 | BI20: =VLOOKUP($BW20,'HR|社保明细'!$C:X,15,0) -> 74.6 | BJ20: =VLOOKUP($BW20,'HR|社保明细'!$C:Y,16,0) -> 0 | BK20: =VLOOKUP($BW20,'HR|社保明细'!$C:Z,17,0) -> 0 | BL20: =SUM(BE20:BK20) -> 1926.17 | BR20: =SUM(BN20:BQ20) -> 0 | BS20: =SUM(V20:AB20) -> 0 | BW20: =C20&I20 -> 开弈人力资源李晓晓 | BY20: 无 | CA20: =VLOOKUP(A20,hr.个税累计数据!C:C,1,0) -> 开弈人力资源李晓晓 | CB20: 开弈人力资源李晓晓 | CD20: =H20=I20 -> TRUE
A21: =C21&I21 -> 开弈人力资源闫秀文 | B21: HRO服务-代收代付残疾人 | C21: 开弈人力资源 | D21: 正常计税 | E21: 客户残疾人 | F21: 葛豪平 | G21: 残疾人 | H21: 闫秀文 | I21: 闫秀文 | J21: 代收代付残疾人 | K21: =AC21+BL21 -> 5449.47 | L21: =AC21-AM21-AX21-AY21+SUM(AZ21:BA21) -> 2740 | N21: 6 | O21: =3457.55+15.54-7.77+50+23.94-15.96 -> 3523.3 | U21: =SUM(O21:T21) -> 3523.3 | AC21: =SUM(O21:T21)+SUM(V21:AB21) -> 3523.3 | AE21: 202606 | AF21: =VLOOKUP(BW21,'HR|社保明细'!C:F,4,0) -> 7460 | AG21: =VLOOKUP($BW21,'HR|社保明细'!$C:G,5,0) -> 0 | AH21: =VLOOKUP($BW21,'HR|社保明细'!$C:H,6,0) -> 596.8 | AI21: =VLOOKUP($BW21,'HR|社保明细'!$C:I,7,0) -> 149.2 | AJ21: =VLOOKUP($BW21,'HR|社保明细'!$C:J,8,0) -> 37.3 | AK21: =VLOOKUP($BW21,'HR|社保明细'!$C:K,9,0) -> 0 | AL21: =VLOOKUP($BW21,'HR|社保明细'!$C:L,10,0) -> 0 | AM21: =SUM(AH21:AL21) -> 783.3 | AS21: =AC21-AM21-SUM(AN21:AR21) -> 2740 | AU21: =VLOOKUP(BW21,hr.个税累计数据!C:DS,121,0) -> 21139.8 | AV21: =IF(AU21-5000*N21-VLOOKUP(A21,hr.个税累计数据!C:DT,122,0)-VLOOKUP(A21,hr.个税累计数据!C:DU,123,0)>0,AU21-5000*N21-VLOOKUP(A21,hr.个税累计数据!C:DT,122,0)-VLOOKUP(A21,hr.个税累计数据!C:DU,123,0),0) -> 0 | AW21: =VLOOKUP(BW21,hr.个税累计数据!C:DV,124,0) -> 0 | AY21: =IF(ROUND(MAX(AV21*{0.03,0.1,0.2,0.25,0.3,0.35,0.45}-{0,210,1410,2660,4410,7160,15160}*12)-AW21,2)<=0,0,ROUND(MAX(AV21*{0.03,0.1,0.2,0.25,0.3,0.35,0.45}-{0,210,1410,2660,4410,7160,15160}*12)-AW21,2)) -> 0 | AZ21: =-S21 -> 0 | BB21: =AC21-AM21-AY21-AX21+SUM(AZ21:BA21) -> 2740 | BD21: =AC21-AM21-AX21-AY21+SUM(AZ21:BA21) -> 2740 | BE21: =VLOOKUP($BW21,'HR|社保明细'!C:T,11,0) -> 1193.6 | BF21: =VLOOKUP($BW21,'HR|社保明细'!$C:U,12,0) -> 596.8 | BG21: =VLOOKUP($BW21,'HR|社保明细'!$C:V,13,0) -> 37.3 | BH21: =VLOOKUP($BW21,'HR|社保明细'!$C:W,14,0) -> 23.87 | BI21: =VLOOKUP($BW21,'HR|社保明细'!$C:X,15,0) -> 74.6 | BJ21: =VLOOKUP($BW21,'HR|社保明细'!$C:Y,16,0) -> 0 | BK21: =VLOOKUP($BW21,'HR|社保明细'!$C:Z,17,0) -> 0 | BL21: =SUM(BE21:BK21) -> 1926.17 | BR21: =SUM(BN21:BQ21) -> 0 | BS21: =SUM(V21:AB21) -> 0 | BW21: =C21&I21 -> 开弈人力资源闫秀文 | BY21: 无 | CA21: =VLOOKUP(A21,hr.个税累计数据!C:C,1,0) -> 开弈人力资源闫秀文 | CB21: 开弈人力资源闫秀文 | CD21: =H21=I21 -> TRUE
A22: =C22&I22 -> 开弈人力资源施宏宇 | B22: HRO服务-代收代付残疾人 | C22: 开弈人力资源 | D22: 正常计税 | E22: 客户残疾人 | F22: 葛豪平 | G22: 残疾人 | H22: 施宏宇 | I22: 施宏宇 | J22: 代收代付残疾人 | K22: =AC22+BL22 -> 5825.47 | L22: =AC22-AM22-AX22-AY22+SUM(AZ22:BA22) -> 2740 | N22: 6 | O22: =3638.55+22.54-7.77+50+23.94-15.96 -> 3711.3 | U22: =SUM(O22:T22) -> 3711.3 | AC22: =SUM(O22:T22)+SUM(V22:AB22) -> 3711.3 | AE22: 202606 | AF22: =VLOOKUP(BW22,'HR|社保明细'!C:F,4,0) -> 7460 | AG22: =VLOOKUP($BW22,'HR|社保明细'!$C:G,5,0) -> 2690 | AH22: =VLOOKUP($BW22,'HR|社保明细'!$C:H,6,0) -> 596.8 | AI22: =VLOOKUP($BW22,'HR|社保明细'!$C:I,7,0) -> 149.2 | AJ22: =VLOOKUP($BW22,'HR|社保明细'!$C:J,8,0) -> 37.3 | AK22: =VLOOKUP($BW22,'HR|社保明细'!$C:K,9,0) -> 188 | AL22: =VLOOKUP($BW22,'HR|社保明细'!$C:L,10,0) -> 0 | AM22: =SUM(AH22:AL22) -> 971.3 | AS22: =AC22-AM22-SUM(AN22:AR22) -> 2740 | AU22: =VLOOKUP(BW22,hr.个税累计数据!C:DS,121,0) -> 22267.8 | AV22: =IF(AU22-5000*N22-VLOOKUP(A22,hr.个税累计数据!C:DT,122,0)-VLOOKUP(A22,hr.个税累计数据!C:DU,123,0)>0,AU22-5000*N22-VLOOKUP(A22,hr.个税累计数据!C:DT,122,0)-VLOOKUP(A22,hr.个税累计数据!C:DU,123,0),0) -> 0 | AW22: =VLOOKUP(BW22,hr.个税累计数据!C:DV,124,0) -> 0 | AY22: =IF(ROUND(MAX(AV22*{0.03,0.1,0.2,0.25,0.3,0.35,0.45}-{0,210,1410,2660,4410,7160,15160}*12)-AW22,2)<=0,0,ROUND(MAX(AV22*{0.03,0.1,0.2,0.25,0.3,0.35,0.45}-{0,210,1410,2660,4410,7160,15160}*12)-AW22,2)) -> 0 | AZ22: =-S22 -> 0 | BB22: =AC22-AM22-AY22-AX22+SUM(AZ22:BA22) -> 2740 | BD22: =AC22-AM22-AX22-AY22+SUM(AZ22:BA22) -> 2740 | BE22: =VLOOKUP($BW22,'HR|社保明细'!C:T,11,0) -> 1193.6 | BF22: =VLOOKUP($BW22,'HR|社保明细'!$C:U,12,0) -> 596.8 | BG22: =VLOOKUP($BW22,'HR|社保明细'!$C:V,13,0) -> 37.3 | BH22: =VLOOKUP($BW22,'HR|社保明细'!$C:W,14,0) -> 23.87 | BI22: =VLOOKUP($BW22,'HR|社保明细'!$C:X,15,0) -> 74.6 | BJ22: =VLOOKUP($BW22,'HR|社保明细'!$C:Y,16,0) -> 188 | BK22: =VLOOKUP($BW22,'HR|社保明细'!$C:Z,17,0) -> 0 | BL22: =SUM(BE22:BK22) -> 2114.17 | BR22: =SUM(BN22:BQ22) -> 0 | BS22: =SUM(V22:AB22) -> 0 | BW22: =C22&I22 -> 开弈人力资源施宏宇 | BY22: 无 | CA22: =VLOOKUP(A22,hr.个税累计数据!C:C,1,0) -> 开弈人力资源施宏宇 | CB22: 开弈人力资源施宏宇 | CD22: =H22=I22 -> TRUE
A23: =C23&I23 -> 开弈人力资源孙文丽 | B23: HRO服务-代收代付残疾人 | C23: 开弈人力资源 | D23: 正常计税 | E23: 客户残疾人 | F23: 葛豪平 | G23: 残疾人 | H23: 孙文丽 | I23: 孙文丽 | J23: 代收代付残疾人 | K23: =AC23+BL23 -> 5449.47 | L23: =AC23-AM23-AX23-AY23+SUM(AZ23:BA23) -> 2740 | N23: 6 | O23: =3457.55+15.54-7.77+50+23.94-15.96 -> 3523.3 | U23: =SUM(O23:T23) -> 3523.3 | AC23: =SUM(O23:T23)+SUM(V23:AB23) -> 3523.3 | AE23: 202606 | AF23: =VLOOKUP(BW23,'HR|社保明细'!C:F,4,0) -> 7460 | AG23: =VLOOKUP($BW23,'HR|社保明细'!$C:G,5,0) -> 0 | AH23: =VLOOKUP($BW23,'HR|社保明细'!$C:H,6,0) -> 596.8 | AI23: =VLOOKUP($BW23,'HR|社保明细'!$C:I,7,0) -> 149.2 | AJ23: =VLOOKUP($BW23,'HR|社保明细'!$C:J,8,0) -> 37.3 | AK23: =VLOOKUP($BW23,'HR|社保明细'!$C:K,9,0) -> 0 | AL23: =VLOOKUP($BW23,'HR|社保明细'!$C:L,10,0) -> 0 | AM23: =SUM(AH23:AL23) -> 783.3 | AS23: =AC23-AM23-SUM(AN23:AR23) -> 2740 | AU23: =VLOOKUP(BW23,hr.个税累计数据!C:DS,121,0) -> 21139.8 | AV23: =IF(AU23-5000*N23-VLOOKUP(A23,hr.个税累计数据!C:DT,122,0)-VLOOKUP(A23,hr.个税累计数据!C:DU,123,0)>0,AU23-5000*N23-VLOOKUP(A23,hr.个税累计数据!C:DT,122,0)-VLOOKUP(A23,hr.个税累计数据!C:DU,123,0),0) -> 0 | AW23: =VLOOKUP(BW23,hr.个税累计数据!C:DV,124,0) -> 0 | AY23: =IF(ROUND(MAX(AV23*{0.03,0.1,0.2,0.25,0.3,0.35,0.45}-{0,210,1410,2660,4410,7160,15160}*12)-AW23,2)<=0,0,ROUND(MAX(AV23*{0.03,0.1,0.2,0.25,0.3,0.35,0.45}-{0,210,1410,2660,4410,7160,15160}*12)-AW23,2)) -> 0 | AZ23: =-S23 -> 0 | BB23: =AC23-AM23-AY23-AX23+SUM(AZ23:BA23) -> 2740 | BD23: =AC23-AM23-AX23-AY23+SUM(AZ23:BA23) -> 2740 | BE23: =VLOOKUP($BW23,'HR|社保明细'!C:T,11,0) -> 1193.6 | BF23: =VLOOKUP($BW23,'HR|社保明细'!$C:U,12,0) -> 596.8 | BG23: =VLOOKUP($BW23,'HR|社保明细'!$C:V,13,0) -> 37.3 | BH23: =VLOOKUP($BW23,'HR|社保明细'!$C:W,14,0) -> 23.87 | BI23: =VLOOKUP($BW23,'HR|社保明细'!$C:X,15,0) -> 74.6 | BJ23: =VLOOKUP($BW23,'HR|社保明细'!$C:Y,16,0) -> 0 | BK23: =VLOOKUP($BW23,'HR|社保明细'!$C:Z,17,0) -> 0 | BL23: =SUM(BE23:BK23) -> 1926.17 | BR23: =SUM(BN23:BQ23) -> 0 | BS23: =SUM(V23:AB23) -> 0 | BW23: =C23&I23 -> 开弈人力资源孙文丽 | BY23: 无 | CA23: =VLOOKUP(A23,hr.个税累计数据!C:C,1,0) -> 开弈人力资源孙文丽 | CB23: 开弈人力资源孙文丽 | CD23: =H23=I23 -> TRUE
A24: =C24&I24 -> 开弈人才谢宁 | B24: HRO服务-代收代付残疾人 | C24: 开弈人才 | D24: 正常计税 | E24: 客户残疾人 | F24: 葛豪平 | G24: 残疾人 | H24: 谢宁 | I24: 谢宁 | J24: 代收代付残疾人 | K24: =AC24+BL24 -> 5449.47 | L24: =AC24-AM24-AX24-AY24+SUM(AZ24:BA24) -> 2740 | N24: 6 | O24: =3457.55+15.54-7.77+50+23.94-15.96 -> 3523.3 | U24: =SUM(O24:T24) -> 3523.3 | AC24: =SUM(O24:T24)+SUM(V24:AB24) -> 3523.3 | AE24: 202606 | AF24: =VLOOKUP(BW24,'HR|社保明细'!C:F,4,0) -> 7460 | AG24: =VLOOKUP($BW24,'HR|社保明细'!$C:G,5,0) -> 0 | AH24: =VLOOKUP($BW24,'HR|社保明细'!$C:H,6,0) -> 596.8 | AI24: =VLOOKUP($BW24,'HR|社保明细'!$C:I,7,0) -> 149.2 | AJ24: =VLOOKUP($BW24,'HR|社保明细'!$C:J,8,0) -> 37.3 | AK24: =VLOOKUP($BW24,'HR|社保明细'!$C:K,9,0) -> 0 | AL24: =VLOOKUP($BW24,'HR|社保明细'!$C:L,10,0) -> 0 | AM24: =SUM(AH24:AL24) -> 783.3 | AS24: =AC24-AM24-SUM(AN24:AR24) -> 2740 | AU24: =VLOOKUP(BW24,hr.个税累计数据!C:DS,121,0) -> 21139.8 | AV24: =IF(AU24-5000*N24-VLOOKUP(A24,hr.个税累计数据!C:DT,122,0)-VLOOKUP(A24,hr.个税累计数据!C:DU,123,0)>0,AU24-5000*N24-VLOOKUP(A24,hr.个税累计数据!C:DT,122,0)-VLOOKUP(A24,hr.个税累计数据!C:DU,123,0),0) -> 0 | AW24: =VLOOKUP(BW24,hr.个税累计数据!C:DV,124,0) -> 0 | AY24: =IF(ROUND(MAX(AV24*{0.03,0.1,0.2,0.25,0.3,0.35,0.45}-{0,210,1410,2660,4410,7160,15160}*12)-AW24,2)<=0,0,ROUND(MAX(AV24*{0.03,0.1,0.2,0.25,0.3,0.35,0.45}-{0,210,1410,2660,4410,7160,15160}*12)-AW24,2)) -> 0 | AZ24: =-S24 -> 0 | BB24: =AC24-AM24-AY24-AX24+SUM(AZ24:BA24) -> 2740 | BD24: =AC24-AM24-AX24-AY24+SUM(AZ24:BA24) -> 2740 | BE24: =VLOOKUP($BW24,'HR|社保明细'!C:T,11,0) -> 1193.6 | BF24: =VLOOKUP($BW24,'HR|社保明细'!$C:U,12,0) -> 596.8 | BG24: =VLOOKUP($BW24,'HR|社保明细'!$C:V,13,0) -> 37.3 | BH24: =VLOOKUP($BW24,'HR|社保明细'!$C:W,14,0) -> 23.87 | BI24: =VLOOKUP($BW24,'HR|社保明细'!$C:X,15,0) -> 74.6 | BJ24: =VLOOKUP($BW24,'HR|社保明细'!$C:Y,16,0) -> 0 | BK24: =VLOOKUP($BW24,'HR|社保明细'!$C:Z,17,0) -> 0 | BL24: =SUM(BE24:BK24) -> 1926.17 | BR24: =SUM(BN24:BQ24) -> 0 | BS24: =SUM(V24:AB24) -> 0 | BW24: =C24&I24 -> 开弈人才谢宁 | BY24: 有 | CA24: =VLOOKUP(A24,hr.个税累计数据!C:C,1,0) -> 开弈人才谢宁 | CB24: 开弈人力资源谢宁 | CD24: =H24=I24 -> TRUE
A25: =C25&I25 -> 开弈人才徐峰 | B25: HRO服务-公司销售部 | C25: 开弈人才 | D25: 正常计税 | E25: 销售部 | F25: 黄一萧 | G25: 销售 | H25: 徐峰 | I25: 徐峰 | J25: 非全日制 | K25: =AC25+BL25 -> 4519.83 | L25: =AC25-AM25-AX25-AY25+SUM(AZ25:BA25) -> 0 | N25: 6 | O25: =1425.55+29.54-14.77+23.94-15.96 -> 1448.3 | Q25: =VLOOKUP(I25,考勤调整记录!I:W,15,0) -> 0 | S25: 480.36 | U25: =SUM(O25:T25) -> 1928.66 | AC25: =SUM(O25:T25)+SUM(V25:AB25) -> 1928.66 | AE25: 202606 | AF25: =VLOOKUP(BW25,'HR|社保明细'!C:F,4,0) -> 7460 | AG25: =VLOOKUP($BW25,'HR|社保明细'!$C:G,5,0) -> 7384 | AH25: =VLOOKUP($BW25,'HR|社保明细'!$C:H,6,0) -> 596.8 | AI25: =VLOOKUP($BW25,'HR|社保明细'!$C:I,7,0) -> 149.2 | AJ25: =VLOOKUP($BW25,'HR|社保明细'!$C:J,8,0) -> 37.3 | AK25: =VLOOKUP($BW25,'HR|社保明细'!$C:K,9,0) -> 517 | AL25: =VLOOKUP($BW25,'HR|社保明细'!$C:L,10,0) -> 148 | AM25: =SUM(AH25:AL25) -> 1448.3 | AQ25: 3000 | AS25: =AC25-AM25-SUM(AN25:AR25) -> -2519.64 | AU25: =VLOOKUP(BW25,hr.个税累计数据!C:DS,121,0) -> 11336.52 | AV25: =IF(AU25-5000*N25-VLOOKUP(A25,hr.个税累计数据!C:DT,122,0)-VLOOKUP(A25,hr.个税累计数据!C:DU,123,0)>0,AU25-5000*N25-VLOOKUP(A25,hr.个税累计数据!C:DT,122,0)-VLOOKUP(A25,hr.个税累计数据!C:DU,123,0),0) -> 0 | AW25: =VLOOKUP(BW25,hr.个税累计数据!C:DV,124,0) -> 0 | AY25: =IF(ROUND(MAX(AV25*{0.03,0.1,0.2,0.25,0.3,0.35,0.45}-{0,210,1410,2660,4410,7160,15160}*12)-AW25,2)<=0,0,ROUND(MAX(AV25*{0.03,0.1,0.2,0.25,0.3,0.35,0.45}-{0,210,1410,2660,4410,7160,15160}*12)-AW25,2)) -> 0 | AZ25: =-S25 -> -480.36 | BB25: =AC25-AM25-AY25-AX25+SUM(AZ25:BA25) -> 0 | BD25: =AC25-AM25-AX25-AY25+SUM(AZ25:BA25) -> 0 | BE25: =VLOOKUP($BW25,'HR|社保明细'!C:T,11,0) -> 1193.6 | BF25: =VLOOKUP($BW25,'HR|社保明细'!$C:U,12,0) -> 596.8 | BG25: =VLOOKUP($BW25,'HR|社保明细'!$C:V,13,0) -> 37.3 | BH25: =VLOOKUP($BW25,'HR|社保明细'!$C:W,14,0) -> 23.87 | BI25: =VLOOKUP($BW25,'HR|社保明细'!$C:X,15,0) -> 74.6 | BJ25: =VLOOKUP($BW25,'HR|社保明细'!$C:Y,16,0) -> 517 | BK25: =VLOOKUP($BW25,'HR|社保明细'!$C:Z,17,0) -> 148 | BL25: =SUM(BE25:BK25) -> 2591.17 | BR25: =SUM(BN25:BQ25) -> 0 | BS25: =SUM(V25:AB25) -> 0 | BW25: =C25&I25 -> 开弈人才徐峰 | BY25: 有 | CA25: =VLOOKUP(A25,hr.个税累计数据!C:C,1,0) -> 开弈人才徐峰 | CB25: 开弈人才徐峰 | CC25: 有 | CD25: =H25=I25 -> TRUE
A26: =C26&I26 -> 开弈人力资源樊涛 | B26: HRO服务-代收代付残疾人 | C26: 开弈人力资源 | D26: 正常计税 | E26: 客户残疾人 | F26: 葛豪平 | G26: 残疾人 | H26: 樊涛 | I26: 樊涛 | J26: 代收代付残疾人 | K26: =AC26+BL26 -> 5449.47 | L26: =AC26-AM26-AX26-AY26+SUM(AZ26:BA26) -> 2740 | N26: 6 | O26: =3457.55+15.54-7.77+50+23.94-15.96 -> 3523.3 | U26: =SUM(O26:T26) -> 3523.3 | AC26: =SUM(O26:T26)+SUM(V26:AB26) -> 3523.3 | AE26: 202606 | AF26: =VLOOKUP(BW26,'HR|社保明细'!C:F,4,0) -> 7460 | AG26: =VLOOKUP($BW26,'HR|社保明细'!$C:G,5,0) -> 0 | AH26: =VLOOKUP($BW26,'HR|社保明细'!$C:H,6,0) -> 596.8 | AI26: =VLOOKUP($BW26,'HR|社保明细'!$C:I,7,0) -> 149.2 | AJ26: =VLOOKUP($BW26,'HR|社保明细'!$C:J,8,0) -> 37.3 | AK26: =VLOOKUP($BW26,'HR|社保明细'!$C:K,9,0) -> 0 | AL26: =VLOOKUP($BW26,'HR|社保明细'!$C:L,10,0) -> 0 | AM26: =SUM(AH26:AL26) -> 783.3 | AS26: =AC26-AM26-SUM(AN26:AR26) -> 2740 | AU26: =VLOOKUP(BW26,hr.个税累计数据!C:DS,121,0) -> 21139.8 | AV26: =IF(AU26-5000*N26-VLOOKUP(A26,hr.个税累计数据!C:DT,122,0)-VLOOKUP(A26,hr.个税累计数据!C:DU,123,0)>0,AU26-5000*N26-VLOOKUP(A26,hr.个税累计数据!C:DT,122,0)-VLOOKUP(A26,hr.个税累计数据!C:DU,123,0),0) -> 0 | AW26: =VLOOKUP(BW26,hr.个税累计数据!C:DV,124,0) -> 0 | AY26: =IF(ROUND(MAX(AV26*{0.03,0.1,0.2,0.25,0.3,0.35,0.45}-{0,210,1410,2660,4410,7160,15160}*12)-AW26,2)<=0,0,ROUND(MAX(AV26*{0.03,0.1,0.2,0.25,0.3,0.35,0.45}-{0,210,1410,2660,4410,7160,15160}*12)-AW26,2)) -> 0 | AZ26: =-S26 -> 0 | BB26: =AC26-AM26-AY26-AX26+SUM(AZ26:BA26) -> 2740 | BD26: =AC26-AM26-AX26-AY26+SUM(AZ26:BA26) -> 2740 | BE26: =VLOOKUP($BW26,'HR|社保明细'!C:T,11,0) -> 1193.6 | BF26: =VLOOKUP($BW26,'HR|社保明细'!$C:U,12,0) -> 596.8 | BG26: =VLOOKUP($BW26,'HR|社保明细'!$C:V,13,0) -> 37.3 | BH26: =VLOOKUP($BW26,'HR|社保明细'!$C:W,14,0) -> 23.87 | BI26: =VLOOKUP($BW26,'HR|社保明细'!$C:X,15,0) -> 74.6 | BJ26: =VLOOKUP($BW26,'HR|社保明细'!$C:Y,16,0) -> 0 | BK26: =VLOOKUP($BW26,'HR|社保明细'!$C:Z,17,0) -> 0 | BL26: =SUM(BE26:BK26) -> 1926.17 | BR26: =SUM(BN26:BQ26) -> 0 | BS26: =SUM(V26:AB26) -> 0 | BW26: =C26&I26 -> 开弈人力资源樊涛 | BY26: 无 | CA26: =VLOOKUP(A26,hr.个税累计数据!C:C,1,0) -> 开弈人力资源樊涛 | CB26: 开弈人力资源樊涛 | CD26: =H26=I26 -> TRUE
A27: =C27&I27 -> 开弈人力资源葛豪平 | B27: Shaun-雇员服务部 | C27: 开弈人力资源 | D27: 正常计税 | E27: 社保部 | F27: 黄一萧 | G27: 社保经理 | H27: 葛豪平 | I27: 葛豪平 | J27: 全日制 | K27: =AC27+BL27 -> 19228.4 | L27: =AC27-AM27-AX27-AY27+SUM(AZ27:BA27) -> 12109.36 | N27: 6 | O27: 15000 | P27: 179 | Q27: =VLOOKUP(I27,考勤调整记录!I:W,15,0) -> 0 | S27: 267.4 | U27: =SUM(O27:T27) -> 15446.4 | AC27: =SUM(O27:T27)+SUM(V27:AB27) -> 15446.4 | AE27: 202606 | AF27: =VLOOKUP(BW27,'HR|社保明细'!C:F,4,0) -> 10000 | AG27: =VLOOKUP($BW27,'HR|社保明细'!$C:G,5,0) -> 10000 | AH27: =VLOOKUP($BW27,'HR|社保明细'!$C:H,6,0) -> 800 | AI27: =VLOOKUP($BW27,'HR|社保明细'!$C:I,7,0) -> 200 | AJ27: =VLOOKUP($BW27,'HR|社保明细'!$C:J,8,0) -> 50 | AK27: =VLOOKUP($BW27,'HR|社保明细'!$C:K,9,0) -> 700 | AL27: =VLOOKUP($BW27,'HR|社保明细'!$C:L,10,0) -> 500 | AM27: =SUM(AH27:AL27) -> 2250 | AS27: =AC27-AM27-SUM(AN27:AR27) -> 13196.4 | AU27: =VLOOKUP(BW27,hr.个税累计数据!C:DS,121,0) -> 106148.35 | AV27: =IF(AU27-5000*N27-VLOOKUP(A27,hr.个税累计数据!C:DT,122,0)-VLOOKUP(A27,hr.个税累计数据!C:DU,123,0)>0,AU27-5000*N27-VLOOKUP(A27,hr.个税累计数据!C:DT,122,0)-VLOOKUP(A27,hr.个税累计数据!C:DU,123,0),0) -> 62648.35 | AW27: =VLOOKUP(BW27,hr.个税累计数据!C:DV,124,0) -> 2925.2 | AY27: =IF(ROUND(MAX(AV27*{0.03,0.1,0.2,0.25,0.3,0.35,0.45}-{0,210,1410,2660,4410,7160,15160}*12)-AW27,2)<=0,0,ROUND(MAX(AV27*{0.03,0.1,0.2,0.25,0.3,0.35,0.45}-{0,210,1410,2660,4410,7160,15160}*12)-AW27,2)) -> 819.64 | AZ27: =-S27 -> -267.4 | BB27: =AC27-AM27-AY27-AX27+SUM(AZ27:BA27) -> 12109.36 | BD27: =AC27-AM27-AX27-AY27+SUM(AZ27:BA27) -> 12109.36 | BE27: =VLOOKUP($BW27,'HR|社保明细'!C:T,11,0) -> 1600 | BF27: =VLOOKUP($BW27,'HR|社保明细'!$C:U,12,0) -> 800 | BG27: =VLOOKUP($BW27,'HR|社保明细'!$C:V,13,0) -> 50 | BH27: =VLOOKUP($BW27,'HR|社保明细'!$C:W,14,0) -> 32 | BI27: =VLOOKUP($BW27,'HR|社保明细'!$C:X,15,0) -> 100 | BJ27: =VLOOKUP($BW27,'HR|社保明细'!$C:Y,16,0) -> 700 | BK27: =VLOOKUP($BW27,'HR|社保明细'!$C:Z,17,0) -> 500 | BL27: =SUM(BE27:BK27) -> 3782 | BR27: =SUM(BN27:BQ27) -> 0 | BS27: =SUM(V27:AB27) -> 0 | BT27: 1250 | BW27: =C27&I27 -> 开弈人力资源葛豪平 | BY27: 有 | BZ27: 人才 | CA27: =VLOOKUP(A27,hr.个税累计数据!C:C,1,0) -> 开弈人力资源葛豪平 | CB27: 开弈人力资源葛豪平 | CC27: 有 | CD27: =H27=I27 -> TRUE
A28: =C28&I28 -> 开弈人力资源侯心怡 | B28: Shaun-客服部 | C28: 开弈人力资源 | D28: 正常计税 | E28: 客服部（S） | F28: 杨漾 | G28: 客服专员 | H28: 侯心怡 | I28: 侯心怡 | J28: 全日制 | K28: =AC28+BL28 -> 12598.97 | L28: =AC28-AM28-AX28-AY28+SUM(AZ28:BA28) -> 8584.03 | N28: 6 | O28: 10000 | Q28: =VLOOKUP(I28,考勤调整记录!I:W,15,0) -> 0 | S28: 155.8 | U28: =SUM(O28:T28) -> 10155.8 | AC28: =SUM(O28:T28)+SUM(V28:AB28) -> 10155.8 | AE28: 202606 | AF28: =VLOOKUP(BW28,'HR|社保明细'!C:F,4,0) -> 7460 | AG28: =VLOOKUP($BW28,'HR|社保明细'!$C:G,5,0) -> 7384 | AH28: =VLOOKUP($BW28,'HR|社保明细'!$C:H,6,0) -> 596.8 | AI28: =VLOOKUP($BW28,'HR|社保明细'!$C:I,7,0) -> 149.2 | AJ28: =VLOOKUP($BW28,'HR|社保明细'!$C:J,8,0) -> 37.3 | AK28: =VLOOKUP($BW28,'HR|社保明细'!$C:K,9,0) -> 517 | AL28: =VLOOKUP($BW28,'HR|社保明细'!$C:L,10,0) -> 0 | AM28: =SUM(AH28:AL28) -> 1300.3 | AS28: =AC28-AM28-SUM(AN28:AR28) -> 8855.5 | AU28: =VLOOKUP(BW28,hr.个税累计数据!C:DS,121,0) -> 63319.98 | AV28: =IF(AU28-5000*N28-VLOOKUP(A28,hr.个税累计数据!C:DT,122,0)-VLOOKUP(A28,hr.个税累计数据!C:DU,123,0)>0,AU28-5000*N28-VLOOKUP(A28,hr.个税累计数据!C:DT,122,0)-VLOOKUP(A28,hr.个税累计数据!C:DU,123,0),0) -> 25518.18 | AW28: =VLOOKUP(BW28,hr.个税累计数据!C:DV,124,0) -> 649.88 | AX28: 0 | AY28: =IF(ROUND(MAX(AV28*{0.03,0.1,0.2,0.25,0.3,0.35,0.45}-{0,210,1410,2660,4410,7160,15160}*12)-AW28,2)<=0,0,ROUND(MAX(AV28*{0.03,0.1,0.2,0.25,0.3,0.35,0.45}-{0,210,1410,2660,4410,7160,15160}*12)-AW28,2)) -> 115.67 | AZ28: =-S28 -> -155.8 | BB28: =AC28-AM28-AY28-AX28+SUM(AZ28:BA28) -> 8584.03 | BD28: =AC28-AM28-AX28-AY28+SUM(AZ28:BA28) -> 8584.03 | BE28: =VLOOKUP($BW28,'HR|社保明细'!C:T,11,0) -> 1193.6 | BF28: =VLOOKUP($BW28,'HR|社保明细'!$C:U,12,0) -> 596.8 | BG28: =VLOOKUP($BW28,'HR|社保明细'!$C:V,13,0) -> 37.3 | BH28: =VLOOKUP($BW28,'HR|社保明细'!$C:W,14,0) -> 23.87 | BI28: =VLOOKUP($BW28,'HR|社保明细'!$C:X,15,0) -> 74.6 | BJ28: =VLOOKUP($BW28,'HR|社保明细'!$C:Y,16,0) -> 517 | BK28: =VLOOKUP($BW28,'HR|社保明细'!$C:Z,17,0) -> 0 | BL28: =SUM(BE28:BK28) -> 2443.17 | BR28: =SUM(BN28:BQ28) -> 0 | BS28: =SUM(V28:AB28) -> 0 | BT28: 1250 | BW28: =C28&I28 -> 开弈人力资源侯心怡 | BY28: 有 | BZ28: 人才 | CA28: =VLOOKUP(A28,hr.个税累计数据!C:C,1,0) -> 开弈人力资源侯心怡 | CB28: 开弈人力资源侯心怡 | CC28: 有 | CD28: =H28=I28 -> TRUE
A29: =C29&I29 -> 开弈人力资源黄一萧 | B29: Shaun-客服部 | C29: 开弈人力资源 | D29: 正常计税 | E29: 客服部（S） | F29: 张毅 | G29: 客服总监 | H29: 黄一萧 | I29: 黄一萧 | J29: 全日制 | K29: =AC29+BL29 -> 23272.68 | L29: =AC29-AM29-AX29-AY29+SUM(AZ29:BA29) -> 13745.05 | N29: 6 | O29: 17100 | P29: 359 | Q29: =VLOOKUP(I29,考勤调整记录!I:W,15,0) -> 0 | S29: 257.16 | T29: 5000 | U29: =SUM(O29:T29) -> 22716.16 | W29: -5116.48 | AC29: =SUM(O29:T29)+SUM(V29:AB29) -> 17599.68 | AE29: 202606 | AF29: =VLOOKUP(BW29,'HR|社保明细'!C:F,4,0) -> 15000 | AG29: =VLOOKUP($BW29,'HR|社保明细'!$C:G,5,0) -> 15000 | AH29: =VLOOKUP($BW29,'HR|社保明细'!$C:H,6,0) -> 1200 | AI29: =VLOOKUP($BW29,'HR|社保明细'!$C:I,7,0) -> 300 | AJ29: =VLOOKUP($BW29,'HR|社保明细'!$C:J,8,0) -> 75 | AK29: =VLOOKUP($BW29,'HR|社保明细'!$C:K,9,0) -> 1050 | AL29: =VLOOKUP($BW29,'HR|社保明细'!$C:L,10,0) -> 750 | AM29: =SUM(AH29:AL29) -> 3375 | AQ29: 3000 | AS29: =AC29-AM29-SUM(AN29:AR29) -> 11224.68 | AU29: =VLOOKUP(BW29,hr.个税累计数据!C:DS,121,0) -> 174340.29 | AV29: =IF(AU29-5000*N29-VLOOKUP(A29,hr.个税累计数据!C:DT,122,0)-VLOOKUP(A29,hr.个税累计数据!C:DU,123,0)>0,AU29-5000*N29-VLOOKUP(A29,hr.个税累计数据!C:DT,122,0)-VLOOKUP(A29,hr.个税累计数据!C:DU,123,0),0) -> 82090.29 | AW29: =VLOOKUP(BW29,hr.个税累计数据!C:DV,124,0) -> 5466.56 | AY29: =IF(ROUND(MAX(AV29*{0.03,0.1,0.2,0.25,0.3,0.35,0.45}-{0,210,1410,2660,4410,7160,15160}*12)-AW29,2)<=0,0,ROUND(MAX(AV29*{0.03,0.1,0.2,0.25,0.3,0.35,0.45}-{0,210,1410,2660,4410,7160,15160}*12)-AW29,2)) -> 222.47 | AZ29: =-S29 -> -257.16 | BB29: =AC29-AM29-AY29-AX29+SUM(AZ29:BA29) -> 13745.05 | BD29: =AC29-AM29-AX29-AY29+SUM(AZ29:BA29) -> 13745.05 | BE29: =VLOOKUP($BW29,'HR|社保明细'!C:T,11,0) -> 2400 | BF29: =VLOOKUP($BW29,'HR|社保明细'!$C:U,12,0) -> 1200 | BG29: =VLOOKUP($BW29,'HR|社保明细'!$C:V,13,0) -> 75 | BH29: =VLOOKUP($BW29,'HR|社保明细'!$C:W,14,0) -> 48 | BI29: =VLOOKUP($BW29,'HR|社保明细'!$C:X,15,0) -> 150 | BJ29: =VLOOKUP($BW29,'HR|社保明细'!$C:Y,16,0) -> 1050 | BK29: =VLOOKUP($BW29,'HR|社保明细'!$C:Z,17,0) -> 750 | BL29: =SUM(BE29:BK29) -> 5673 | BR29: =SUM(BN29:BQ29) -> 0 | BS29: =SUM(V29:AB29) -> -5116.48 | BT29: 1250 | BW29: =C29&I29 -> 开弈人力资源黄一萧 | BY29: 有 | BZ29: 人才 | CA29: =VLOOKUP(A29,hr.个税累计数据!C:C,1,0) -> 开弈人力资源黄一萧 | CB29: 开弈人力资源黄一萧 | CC29: 有 | CD29: =H29=I29 -> TRUE
A30: =C30&I30 -> 开弈人力资源肖宝仙 | B30: Shaun-客服部 | C30: 开弈人力资源 | D30: 正常计税 | E30: 客服部（S） | F30: 黄一萧 | G30: 顾问 | H30: 黄一萧 | I30: 肖宝仙 | J30: 非全日制 | K30: =AC30+BL30 -> 10000 | L30: =AC30-AM30-AX30-AY30+SUM(AZ30:BA30) -> 9850 | N30: 6 | O30: 10000 | Q30: =VLOOKUP(I30,考勤调整记录!I:W,15,0) -> 0 | U30: =SUM(O30:T30) -> 10000 | AC30: =SUM(O30:T30)+SUM(V30:AB30) -> 10000 | AE30: 202606 | AF30: =VLOOKUP(BW30,'HR|社保明细'!C:F,4,0) -> 0 | AG30: =VLOOKUP($BW30,'HR|社保明细'!$C:G,5,0) -> 0 | AH30: =VLOOKUP($BW30,'HR|社保明细'!$C:H,6,0) -> 0 | AI30: =VLOOKUP($BW30,'HR|社保明细'!$C:I,7,0) -> 0 | AJ30: =VLOOKUP($BW30,'HR|社保明细'!$C:J,8,0) -> 0 | AK30: =VLOOKUP($BW30,'HR|社保明细'!$C:K,9,0) -> 0 | AL30: =VLOOKUP($BW30,'HR|社保明细'!$C:L,10,0) -> 0 | AM30: =SUM(AH30:AL30) -> 0 | AS30: =AC30-AM30-SUM(AN30:AR30) -> 10000 | AU30: =VLOOKUP(BW30,hr.个税累计数据!C:DS,121,0) -> 58329 | AV30: =IF(AU30-5000*N30-VLOOKUP(A30,hr.个税累计数据!C:DT,122,0)-VLOOKUP(A30,hr.个税累计数据!C:DU,123,0)>0,AU30-5000*N30-VLOOKUP(A30,hr.个税累计数据!C:DT,122,0)-VLOOKUP(A30,hr.个税累计数据!C:DU,123,0),0) -> 28329 | AW30: =VLOOKUP(BW30,hr.个税累计数据!C:DV,124,0) -> 699.87 | AY30: =IF(ROUND(MAX(AV30*{0.03,0.1,0.2,0.25,0.3,0.35,0.45}-{0,210,1410,2660,4410,7160,15160}*12)-AW30,2)<=0,0,ROUND(MAX(AV30*{0.03,0.1,0.2,0.25,0.3,0.35,0.45}-{0,210,1410,2660,4410,7160,15160}*12)-AW30,2)) -> 150 | AZ30: =-S30 -> 0 | BB30: =AC30-AM30-AY30-AX30+SUM(AZ30:BA30) -> 9850 | BD30: =AC30-AM30-AX30-AY30+SUM(AZ30:BA30) -> 9850 | BE30: =VLOOKUP($BW30,'HR|社保明细'!C:T,11,0) -> 0 | BF30: =VLOOKUP($BW30,'HR|社保明细'!$C:U,12,0) -> 0 | BG30: =VLOOKUP($BW30,'HR|社保明细'!$C:V,13,0) -> 0 | BH30: =VLOOKUP($BW30,'HR|社保明细'!$C:W,14,0) -> 0 | BI30: =VLOOKUP($BW30,'HR|社保明细'!$C:X,15,0) -> 0 | BJ30: =VLOOKUP($BW30,'HR|社保明细'!$C:Y,16,0) -> 0 | BK30: =VLOOKUP($BW30,'HR|社保明细'!$C:Z,17,0) -> 0 | BL30: =SUM(BE30:BK30) -> 0 | BR30: =SUM(BN30:BQ30) -> 0 | BS30: =SUM(V30:AB30) -> 0 | BW30: =C30&I30 -> 开弈人力资源肖宝仙 | BX30: 无社公 | BY30: 无 | BZ30: 人才 | CA30: =VLOOKUP(A30,hr.个税累计数据!C:C,1,0) -> 开弈人力资源肖宝仙 | CB30: 开弈人力资源肖宝仙 | CD30: =H30=I30 -> FALSE
A31: =C31&I31 -> 开弈人力资源李家东 | B31: HRO服务-代收代付残疾人 | C31: 开弈人力资源 | D31: 正常计税 | E31: 客户残疾人 | F31: 葛豪平 | G31: 残疾人 | H31: 李家东 | I31: 李家东 | J31: 代收代付残疾人 | K31: =AC31+BL31 -> 5449.47 | L31: =AC31-AM31-AX31-AY31+SUM(AZ31:BA31) -> 2740 | N31: 6 | O31: =3457.55+15.54-7.77+50+23.94-15.96 -> 3523.3 | U31: =SUM(O31:T31) -> 3523.3 | AC31: =SUM(O31:T31)+SUM(V31:AB31) -> 3523.3 | AE31: 202606 | AF31: =VLOOKUP(BW31,'HR|社保明细'!C:F,4,0) -> 7460 | AG31: =VLOOKUP($BW31,'HR|社保明细'!$C:G,5,0) -> 0 | AH31: =VLOOKUP($BW31,'HR|社保明细'!$C:H,6,0) -> 596.8 | AI31: =VLOOKUP($BW31,'HR|社保明细'!$C:I,7,0) -> 149.2 | AJ31: =VLOOKUP($BW31,'HR|社保明细'!$C:J,8,0) -> 37.3 | AK31: =VLOOKUP($BW31,'HR|社保明细'!$C:K,9,0) -> 0 | AL31: =VLOOKUP($BW31,'HR|社保明细'!$C:L,10,0) -> 0 | AM31: =SUM(AH31:AL31) -> 783.3 | AS31: =AC31-AM31-SUM(AN31:AR31) -> 2740 | AU31: =VLOOKUP(BW31,hr.个税累计数据!C:DS,121,0) -> 21139.8 | AV31: =IF(AU31-5000*N31-VLOOKUP(A31,hr.个税累计数据!C:DT,122,0)-VLOOKUP(A31,hr.个税累计数据!C:DU,123,0)>0,AU31-5000*N31-VLOOKUP(A31,hr.个税累计数据!C:DT,122,0)-VLOOKUP(A31,hr.个税累计数据!C:DU,123,0),0) -> 0 | AW31: =VLOOKUP(BW31,hr.个税累计数据!C:DV,124,0) -> 0 | AY31: =IF(ROUND(MAX(AV31*{0.03,0.1,0.2,0.25,0.3,0.35,0.45}-{0,210,1410,2660,4410,7160,15160}*12)-AW31,2)<=0,0,ROUND(MAX(AV31*{0.03,0.1,0.2,0.25,0.3,0.35,0.45}-{0,210,1410,2660,4410,7160,15160}*12)-AW31,2)) -> 0 | AZ31: =-S31 -> 0 | BB31: =AC31-AM31-AY31-AX31+SUM(AZ31:BA31) -> 2740 | BD31: =AC31-AM31-AX31-AY31+SUM(AZ31:BA31) -> 2740 | BE31: =VLOOKUP($BW31,'HR|社保明细'!C:T,11,0) -> 1193.6 | BF31: =VLOOKUP($BW31,'HR|社保明细'!$C:U,12,0) -> 596.8 | BG31: =VLOOKUP($BW31,'HR|社保明细'!$C:V,13,0) -> 37.3 | BH31: =VLOOKUP($BW31,'HR|社保明细'!$C:W,14,0) -> 23.87 | BI31: =VLOOKUP($BW31,'HR|社保明细'!$C:X,15,0) -> 74.6 | BJ31: =VLOOKUP($BW31,'HR|社保明细'!$C:Y,16,0) -> 0 | BK31: =VLOOKUP($BW31,'HR|社保明细'!$C:Z,17,0) -> 0 | BL31: =SUM(BE31:BK31) -> 1926.17 | BR31: =SUM(BN31:BQ31) -> 0 | BS31: =SUM(V31:AB31) -> 0 | BW31: =C31&I31 -> 开弈人力资源李家东 | BY31: 无 | CA31: =VLOOKUP(A31,hr.个税累计数据!C:C,1,0) -> 开弈人力资源李家东 | CB31: 开弈人力资源李家东 | CD31: =H31=I31 -> TRUE
A32: =C32&I32 -> 开弈人力资源卢素丹 | B32: Shaun-客服部 | C32: 开弈人力资源 | D32: 正常计税 | E32: 客服部（S） | F32: 杨漾 | G32: 客服专员 | H32: 卢素丹 | I32: 卢素丹 | J32: 全日制 | K32: =AC32+BL32 -> 10598.97 | L32: =AC32-AM32-AX32-AY32+SUM(AZ32:BA32) -> 6644.03 | N32: 6 | O32: 8000 | Q32: =VLOOKUP(I32,考勤调整记录!I:W,15,0) -> 0 | S32: 155.8 | U32: =SUM(O32:T32) -> 8155.8 | AC32: =SUM(O32:T32)+SUM(V32:AB32) -> 8155.8 | AE32: 202606 | AF32: =VLOOKUP(BW32,'HR|社保明细'!C:F,4,0) -> 7460 | AG32: =VLOOKUP($BW32,'HR|社保明细'!$C:G,5,0) -> 7384 | AH32: =VLOOKUP($BW32,'HR|社保明细'!$C:H,6,0) -> 596.8 | AI32: =VLOOKUP($BW32,'HR|社保明细'!$C:I,7,0) -> 149.2 | AJ32: =VLOOKUP($BW32,'HR|社保明细'!$C:J,8,0) -> 37.3 | AK32: =VLOOKUP($BW32,'HR|社保明细'!$C:K,9,0) -> 517 | AL32: =VLOOKUP($BW32,'HR|社保明细'!$C:L,10,0) -> 0 | AM32: =SUM(AH32:AL32) -> 1300.3 | AS32: =AC32-AM32-SUM(AN32:AR32) -> 6855.5 | AU32: =VLOOKUP(BW32,hr.个税累计数据!C:DS,121,0) -> 51052 | AV32: =IF(AU32-5000*N32-VLOOKUP(A32,hr.个税累计数据!C:DT,122,0)-VLOOKUP(A32,hr.个税累计数据!C:DU,123,0)>0,AU32-5000*N32-VLOOKUP(A32,hr.个税累计数据!C:DT,122,0)-VLOOKUP(A32,hr.个税累计数据!C:DU,123,0),0) -> 13250.2 | AW32: =VLOOKUP(BW32,hr.个税累计数据!C:DV,124,0) -> 341.84 | AY32: =IF(ROUND(MAX(AV32*{0.03,0.1,0.2,0.25,0.3,0.35,0.45}-{0,210,1410,2660,4410,7160,15160}*12)-AW32,2)<=0,0,ROUND(MAX(AV32*{0.03,0.1,0.2,0.25,0.3,0.35,0.45}-{0,210,1410,2660,4410,7160,15160}*12)-AW32,2)) -> 55.67 | AZ32: =-S32 -> -155.8 | BB32: =AC32-AM32-AY32-AX32+SUM(AZ32:BA32) -> 6644.03 | BD32: =AC32-AM32-AX32-AY32+SUM(AZ32:BA32) -> 6644.03 | BE32: =VLOOKUP($BW32,'HR|社保明细'!C:T,11,0) -> 1193.6 | BF32: =VLOOKUP($BW32,'HR|社保明细'!$C:U,12,0) -> 596.8 | BG32: =VLOOKUP($BW32,'HR|社保明细'!$C:V,13,0) -> 37.3 | BH32: =VLOOKUP($BW32,'HR|社保明细'!$C:W,14,0) -> 23.87 | BI32: =VLOOKUP($BW32,'HR|社保明细'!$C:X,15,0) -> 74.6 | BJ32: =VLOOKUP($BW32,'HR|社保明细'!$C:Y,16,0) -> 517 | BK32: =VLOOKUP($BW32,'HR|社保明细'!$C:Z,17,0) -> 0 | BL32: =SUM(BE32:BK32) -> 2443.17 | BR32: =SUM(BN32:BQ32) -> 0 | BS32: =SUM(V32:AB32) -> 0 | BT32: 1250 | BW32: =C32&I32 -> 开弈人力资源卢素丹 | BY32: 有 | BZ32: 人才 | CA32: =VLOOKUP(A32,hr.个税累计数据!C:C,1,0) -> 开弈人力资源卢素丹 | CB32: 开弈人力资源卢素丹 | CC32: 有 | CD32: =H32=I32 -> TRUE
A33: =C33&I33 -> 开弈人力资源芦智蔚 | B33: F-大财务部 | C33: 开弈人力资源 | D33: 正常计税 | E33: 财务部 | F33: 张毅 | G33: 财务经理 | H33: 芦智蔚 | I33: 芦智蔚 | J33: 全日制 | K33: =AC33+BL33 -> 35520.36 | L33: =AC33-AM33-AX33-AY33+SUM(AZ33:BA33) -> 25513.5 | N33: 6 | O33: 20000 | Q33: =VLOOKUP(I33,考勤调整记录!I:W,15,0) -> 0 | S33: 480.36 | U33: =SUM(O33:T33) -> 20480.36 | W33: =ROUND((O33)*(0.9629-1),2) -> -742 | Z33: 12000 | AC33: =SUM(O33:T33)+SUM(V33:AB33) -> 31738.36 | AE33: 202606 | AF33: =VLOOKUP(BW33,'HR|社保明细'!C:F,4,0) -> 10000 | AG33: =VLOOKUP($BW33,'HR|社保明细'!$C:G,5,0) -> 10000 | AH33: =VLOOKUP($BW33,'HR|社保明细'!$C:H,6,0) -> 800 | AI33: =VLOOKUP($BW33,'HR|社保明细'!$C:I,7,0) -> 200 | AJ33: =VLOOKUP($BW33,'HR|社保明细'!$C:J,8,0) -> 50 | AK33: =VLOOKUP($BW33,'HR|社保明细'!$C:K,9,0) -> 700 | AL33: =VLOOKUP($BW33,'HR|社保明细'!$C:L,10,0) -> 500 | AM33: =SUM(AH33:AL33) -> 2250 | AQ33: 1500 | AS33: =AC33-AM33-SUM(AN33:AR33) -> 27988.36 | AU33: =VLOOKUP(BW33,hr.个税累计数据!C:DS,121,0) -> 208456.72 | AV33: =IF(AU33-5000*N33-VLOOKUP(A33,hr.个税累计数据!C:DT,122,0)-VLOOKUP(A33,hr.个税累计数据!C:DU,123,0)>0,AU33-5000*N33-VLOOKUP(A33,hr.个税累计数据!C:DT,122,0)-VLOOKUP(A33,hr.个税累计数据!C:DU,123,0),0) -> 155956.72 | AW33: =VLOOKUP(BW33,hr.个税累计数据!C:DV,124,0) -> 10776.84 | AY33: =IF(ROUND(MAX(AV33*{0.03,0.1,0.2,0.25,0.3,0.35,0.45}-{0,210,1410,2660,4410,7160,15160}*12)-AW33,2)<=0,0,ROUND(MAX(AV33*{0.03,0.1,0.2,0.25,0.3,0.35,0.45}-{0,210,1410,2660,4410,7160,15160}*12)-AW33,2)) -> 3494.5 | AZ33: =-S33 -> -480.36 | BB33: =AC33-AM33-AY33-AX33+SUM(AZ33:BA33) -> 25513.5 | BD33: =AC33-AM33-AX33-AY33+SUM(AZ33:BA33) -> 25513.5 | BE33: =VLOOKUP($BW33,'HR|社保明细'!C:T,11,0) -> 1600 | BF33: =VLOOKUP($BW33,'HR|社保明细'!$C:U,12,0) -> 800 | BG33: =VLOOKUP($BW33,'HR|社保明细'!$C:V,13,0) -> 50 | BH33: =VLOOKUP($BW33,'HR|社保明细'!$C:W,14,0) -> 32 | BI33: =VLOOKUP($BW33,'HR|社保明细'!$C:X,15,0) -> 100 | BJ33: =VLOOKUP($BW33,'HR|社保明细'!$C:Y,16,0) -> 700 | BK33: =VLOOKUP($BW33,'HR|社保明细'!$C:Z,17,0) -> 500 | BL33: =SUM(BE33:BK33) -> 3782 | BR33: =SUM(BN33:BQ33) -> 0 | BS33: =SUM(V33:AB33) -> 11258 | BT33: 1250 | BW33: =C33&I33 -> 开弈人力资源芦智蔚 | BY33: 有 | BZ33: 后台 | CA33: =VLOOKUP(A33,hr.个税累计数据!C:C,1,0) -> 开弈人力资源芦智蔚 | CB33: 开弈人力资源芦智蔚 | CC33: 有 | CD33: =H33=I33 -> TRUE
A34: =C34&I34 -> 靠普人力毛华英 | B34: Shaun-雇员服务部 | C34: 靠普人力 | D34: 正常计税 | E34: 社保部 | F34: 葛豪平 | G34: 社保专员 | H34: 毛华英 | I34: 毛华英 | J34: 全日制 | K34: =AC34+BL34 -> 9892.07 | L34: =AC34-AM34-AX34-AY34+SUM(AZ34:BA34) -> 5958.34 | N34: 6 | O34: 7500 | Q34: =VLOOKUP(I34,考勤调整记录!I:W,15,0) -> -206.9 | S34: 155.8 | U34: =SUM(O34:T34) -> 7448.9 | AC34: =SUM(O34:T34)+SUM(V34:AB34) -> 7448.9 | AE34: 202606 | AF34: =VLOOKUP(BW34,'HR|社保明细'!C:F,4,0) -> 7460 | AG34: =VLOOKUP($BW34,'HR|社保明细'!$C:G,5,0) -> 7384 | AH34: =VLOOKUP($BW34,'HR|社保明细'!$C:H,6,0) -> 596.8 | AI34: =VLOOKUP($BW34,'HR|社保明细'!$C:I,7,0) -> 149.2 | AJ34: =VLOOKUP($BW34,'HR|社保明细'!$C:J,8,0) -> 37.3 | AK34: =VLOOKUP($BW34,'HR|社保明细'!$C:K,9,0) -> 517 | AL34: =VLOOKUP($BW34,'HR|社保明细'!$C:L,10,0) -> 0 | AM34: =SUM(AH34:AL34) -> 1300.3 | AS34: =AC34-AM34-SUM(AN34:AR34) -> 6148.6 | AU34: =VLOOKUP(BW34,hr.个税累计数据!C:DS,121,0) -> 51139.43 | AV34: =IF(AU34-5000*N34-VLOOKUP(A34,hr.个税累计数据!C:DT,122,0)-VLOOKUP(A34,hr.个税累计数据!C:DU,123,0)>0,AU34-5000*N34-VLOOKUP(A34,hr.个税累计数据!C:DT,122,0)-VLOOKUP(A34,hr.个税累计数据!C:DU,123,0),0) -> 13337.63 | AW34: =VLOOKUP(BW34,hr.个税累计数据!C:DV,124,0) -> 365.67 | AY34: =IF(ROUND(MAX(AV34*{0.03,0.1,0.2,0.25,0.3,0.35,0.45}-{0,210,1410,2660,4410,7160,15160}*12)-AW34,2)<=0,0,ROUND(MAX(AV34*{0.03,0.1,0.2,0.25,0.3,0.35,0.45}-{0,210,1410,2660,4410,7160,15160}*12)-AW34,2)) -> 34.46 | AZ34: =-S34 -> -155.8 | BB34: =AC34-AM34-AY34-AX34+SUM(AZ34:BA34) -> 5958.34 | BD34: =AC34-AM34-AX34-AY34+SUM(AZ34:BA34) -> 5958.34 | BE34: =VLOOKUP($BW34,'HR|社保明细'!C:T,11,0) -> 1193.6 | BF34: =VLOOKUP($BW34,'HR|社保明细'!$C:U,12,0) -> 596.8 | BG34: =VLOOKUP($BW34,'HR|社保明细'!$C:V,13,0) -> 37.3 | BH34: =VLOOKUP($BW34,'HR|社保明细'!$C:W,14,0) -> 23.87 | BI34: =VLOOKUP($BW34,'HR|社保明细'!$C:X,15,0) -> 74.6 | BJ34: =VLOOKUP($BW34,'HR|社保明细'!$C:Y,16,0) -> 517 | BK34: =VLOOKUP($BW34,'HR|社保明细'!$C:Z,17,0) -> 0 | BL34: =SUM(BE34:BK34) -> 2443.17 | BR34: =SUM(BN34:BQ34) -> 0 | BS34: =SUM(V34:AB34) -> 0 | BT34: 1250 | BW34: =C34&I34 -> 靠普人力毛华英 | BY34: 有 | BZ34: 人才 | CA34: =VLOOKUP(A34,hr.个税累计数据!C:C,1,0) -> 靠普人力毛华英 | CB34: 靠普人力毛华英 | CC34: 有 | CD34: =H34=I34 -> TRUE
